2019-03-04 09:55:26.092538 INFO protobuf_parser.py:199 Fanning out RPC
2019-03-04 09:55:36.104498 DBG http_handler.py:297 Gathering node data
2019-03-04 09:55:38.107067 ERROR fanout.py:93 Gathering node data
2019-03-04 09:55:42.112449 INFO rpc_client.py:67 Fanning out RPC
2019-03-04 09:55:46.118050 INFO protobuf_parser.py:191 Generated binary file
2019-03-04 09:56:07.149800 DBG task_generator.py:39 Gathering logs from all nodes
2019-03-04 09:56:16.161559 ERROR gflags_handler.py:41 Gathering node data
2019-03-04 09:56:23.171074 INFO db_read.py:23 Gathering node data
2019-03-04 09:56:25.173551 INFO db_write.py:396 Gathering logs from all nodes
2019-03-04 09:56:40.190960 INFO http_handler.py:180 Generated binary file
2019-03-04 09:56:47.199026 INFO protobuf_parser.py:160 Creating task
2019-03-04 09:56:50.202949 ERROR scheduler.py:162 Generated binary file
2019-03-04 09:56:51.204262 INFO wsgi_handler.py:343 Fanning out RPC
2019-03-04 09:56:55.209976 DBG task_generator.py:223 Node destroyed
Traceback (most recent call last):
  File "./random_traceback.py", line 98, in get_random_error_string
  File "./random_traceback.py", line 59, in get_data
InvalidArgumentError: Provided too many arguments
2019-03-04 09:56:58.214241 DBG rpc_client.py:76 Node created
2019-03-04 09:57:00.216577 INFO rpc_client.py:393 Combining logs from all nodes into single log file
2019-03-04 09:57:03.220507 DBG fanout.py:332 Node destroyed
2019-03-04 09:57:05.223368 DBG fanout.py:50 Fanning out RPC
2019-03-04 09:57:09.228449 INFO wsgi_handler.py:113 Creating task
2019-03-04 09:57:12.232338 ERROR fanout.py:142 Node created
2019-03-04 09:57:19.240404 DBG alert_manager.py:338 Gathering node data
2019-03-04 09:57:20.241981 INFO db_write.py:215 Creating task
2019-03-04 09:57:25.248713 ERROR scheduler.py:79 Gathering logs from all nodes
2019-03-04 09:57:28.252628 DBG db_read.py:76 Node created
2019-03-04 09:57:35.260697 ERROR alert_manager.py:363 Node destroyed
Traceback (most recent call last):
  File "./random_traceback.py", line 98, in get_random_error_string
  File "./random_traceback.py", line 53, in get_data
  File "./random_traceback.py", line 70, in extract_metadata
BadRequestError: Request buffer too small
2019-03-04 09:57:54.284268 DBG ssh_tunnel.py:283 Gathering logs from all nodes
2019-03-04 09:58:08.300200 ERROR rpc_client.py:237 Fanning out RPC
2019-03-04 09:58:11.303607 INFO fanout.py:397 Gathering logs from all nodes
2019-03-04 09:58:16.309201 INFO wsgi_handler.py:44 Node created
2019-03-04 09:58:21.314390 DBG db_write.py:238 Node destroyed
2019-03-04 09:58:22.314948 ERROR ssh_tunnel.py:171 Gathering node data
2019-03-04 09:58:34.329632 ERROR rpc_client.py:234 Node created
2019-03-04 09:58:36.331595 INFO task_generator.py:276 Node destroyed
2019-03-04 09:58:38.334232 INFO db_read.py:143 Node created
2019-03-04 09:58:39.335040 DBG db_write.py:301 Generated binary file
2019-03-04 09:58:40.336360 ERROR task_generator.py:349 Combining logs from all nodes into single log file
2019-03-04 09:58:45.342539 INFO http_handler.py:143 Creating task
Traceback (most recent call last):
  File "./random_traceback.py", line 98, in get_random_error_string
  File "./random_traceback.py", line 53, in get_data
  File "./random_traceback.py", line 64, in extract_metadata
  File "./random_traceback.py", line 88, in get_attributes
  File "./random_traceback.py", line 92, in get_attributes
BadRequestError: Special Characters not allowed
2019-03-04 09:59:04.365851 ERROR gflags_handler.py:25 Gathering logs from all nodes
Traceback (most recent call last):
  File "./random_traceback.py", line 103, in get_random_error_string
  File "./random_traceback.py", line 70, in extract_metadata
InvalidArgumentError: Provided too many arguments
2019-03-04 09:59:11.375119 INFO scheduler.py:345 Node destroyed
2019-03-04 09:59:12.376426 ERROR alert_manager.py:129 Generated binary file
2019-03-04 09:59:17.383005 ERROR db_write.py:372 Node created
2019-03-04 09:59:18.384316 DBG gflags_handler.py:191 Fanning out RPC
2019-03-04 09:59:19.385614 ERROR task_generator.py:60 Gathering logs from all nodes
2019-03-04 09:59:24.391012 DBG protobuf_parser.py:228 Node destroyed
2019-03-04 09:59:30.398862 INFO log_collector.py:275 Gathering logs from all nodes
2019-03-04 10:00:00.437427 ERROR scheduler.py:72 Node destroyed
2019-03-04 10:00:06.444129 DBG db_write.py:303 Gathering node data
2019-03-04 10:00:10.449100 ERROR db_read.py:298 Generated binary file
2019-03-04 10:00:12.451771 ERROR wsgi_handler.py:394 Gathering logs from all nodes
2019-03-04 10:00:17.458144 INFO scheduler.py:119 Fanning out RPC
Traceback (most recent call last):
  File "./random_traceback.py", line 103, in get_random_error_string
  File "./random_traceback.py", line 70, in extract_metadata
InvalidArgumentError: Unable to parse arguments
2019-03-04 10:00:21.463421 ERROR db_read.py:107 Creating task
2019-03-04 10:00:30.474992 ERROR protobuf_parser.py:136 Fanning out RPC
2019-03-04 10:00:33.478840 INFO rpc_client.py:248 Creating task
Traceback (most recent call last):
  File "./random_traceback.py", line 103, in get_random_error_string
  File "./random_traceback.py", line 70, in extract_metadata
BadRequestError: Request buffer too small
2019-03-04 10:00:43.490994 INFO scheduler.py:268 Fanning out RPC
2019-03-04 10:00:44.492289 DBG gflags_handler.py:24 Generated binary file
Traceback (most recent call last):
  File "./random_traceback.py", line 103, in get_random_error_string
  File "./random_traceback.py", line 64, in extract_metadata
  File "./random_traceback.py", line 92, in get_attributes
BasicAuthRequiredError: Authentication not provided
2019-03-04 10:01:04.518942 INFO http_handler.py:288 Node destroyed
2019-03-04 10:01:12.529503 DBG alert_manager.py:29 Creating task
2019-03-04 10:01:20.539875 INFO protobuf_parser.py:279 Fanning out RPC
2019-03-04 10:01:22.542454 DBG wsgi_handler.py:261 Creating task
2019-03-04 10:01:23.543731 DBG db_read.py:77 Fanning out RPC
2019-03-04 10:01:31.554130 DBG scheduler.py:195 Generated binary file
2019-03-04 10:01:33.556848 ERROR ssh_tunnel.py:170 Node destroyed
2019-03-04 10:01:52.581463 INFO ssh_tunnel.py:196 Node created
2019-03-04 10:01:55.585317 ERROR db_read.py:102 Fanning out RPC
2019-03-04 10:01:59.590527 DBG http_handler.py:256 Gathering node data
2019-03-04 10:02:03.595728 INFO db_read.py:280 Node destroyed
Traceback (most recent call last):
  File "./random_traceback.py", line 103, in get_random_error_string
  File "./random_traceback.py", line 70, in extract_metadata
BadRequestError: Malformed request
2019-03-04 10:02:13.609586 ERROR wsgi_handler.py:361 Creating task
2019-03-04 10:02:20.618836 ERROR task_generator.py:391 Fanning out RPC
2019-03-04 10:02:28.630246 ERROR wsgi_handler.py:263 Fanning out RPC
2019-03-04 10:02:44.653043 ERROR db_read.py:235 Combining logs from all nodes into single log file
2019-03-04 10:02:47.657815 ERROR db_read.py:274 Node created
Traceback (most recent call last):
  File "./random_traceback.py", line 98, in get_random_error_string
  File "./random_traceback.py", line 53, in get_data
  File "./random_traceback.py", line 64, in extract_metadata
  File "./random_traceback.py", line 86, in get_attributes
  File "./random_traceback.py", line 55, in get_data
  File "./random_traceback.py", line 77, in return_output
  File "./random_traceback.py", line 59, in get_data
MissingAttributeError: Attribute missing
2019-03-04 10:02:50.662617 ERROR protobuf_parser.py:119 Gathering logs from all nodes
2019-03-04 10:02:51.663938 DBG rpc_client.py:65 Generated binary file
2019-03-04 10:02:59.674613 ERROR db_read.py:234 Combining logs from all nodes into single log file
2019-03-04 10:03:03.679720 DBG protobuf_parser.py:64 Node created
2019-03-04 10:03:06.683662 DBG http_handler.py:301 Gathering logs from all nodes
2019-03-04 10:03:08.686346 DBG protobuf_parser.py:203 Creating task
2019-03-04 10:03:09.687627 ERROR gflags_handler.py:218 Gathering node data
2019-03-04 10:03:28.711887 INFO db_write.py:138 Gathering node data
2019-03-04 10:03:38.724080 INFO gflags_handler.py:183 Gathering logs from all nodes
2019-03-04 10:03:41.727970 ERROR http_handler.py:348 Node destroyed
2019-03-04 10:03:43.730626 DBG audit_logger.py:349 Node destroyed
2019-03-04 10:03:47.735762 DBG publisher.py:159 Combining logs from all nodes into single log file
Traceback (most recent call last):
  File "./random_traceback.py", line 113, in get_random_error_string
  File "./random_traceback.py", line 88, in get_attributes
  File "./random_traceback.py", line 86, in get_attributes
  File "./random_traceback.py", line 53, in get_data
  File "./random_traceback.py", line 66, in extract_metadata
  File "./random_traceback.py", line 81, in return_output
ConflictError: Conflicting data types
2019-03-04 10:04:01.753641 ERROR gflags_handler.py:219 Gathering logs from all nodes
2019-03-04 10:04:06.759906 INFO task_generator.py:26 Combining logs from all nodes into single log file
2019-03-04 10:04:09.762950 INFO http_handler.py:251 Gathering logs from all nodes
2019-03-04 10:04:10.764092 INFO protobuf_parser.py:223 Node destroyed
2019-03-04 10:04:18.774845 ERROR alert_manager.py:298 Creating task
2019-03-04 10:04:30.789447 DBG wsgi_handler.py:376 Gathering logs from all nodes
2019-03-04 10:04:31.790747 ERROR task_generator.py:253 Fanning out RPC
2019-03-04 10:04:37.798593 ERROR task_generator.py:280 Gathering logs from all nodes
2019-03-04 10:04:41.803865 INFO scheduler.py:224 Fanning out RPC
2019-03-04 10:04:45.807058 INFO http_handler.py:161 Node created
2019-03-04 10:04:46.808282 INFO protobuf_parser.py:274 Gathering logs from all nodes
2019-03-04 10:05:02.828309 DBG db_read.py:165 Node created
2019-03-04 10:05:10.838731 DBG publisher.py:160 Combining logs from all nodes into single log file
2019-03-04 10:05:11.840045 INFO http_handler.py:199 Generated binary file
2019-03-04 10:05:12.841374 INFO task_generator.py:201 Gathering node data
2019-03-04 10:05:17.847966 ERROR task_generator.py:144 Node created
2019-03-04 10:05:20.851897 DBG scheduler.py:390 Creating task
2019-03-04 10:05:29.863578 DBG gflags_handler.py:216 Creating task
2019-03-04 10:05:33.868704 ERROR wsgi_handler.py:360 Generated binary file
