2019-03-04 09:55:22.086965 ERROR gflags_handler.py:211 Node created
2019-03-04 09:55:32.099101 ERROR http_handler.py:130 Node destroyed
2019-03-04 09:55:34.101543 INFO log_collector.py:33 Creating task
2019-03-04 09:55:35.102845 INFO db_read.py:234 Gathering node data
2019-03-04 09:55:39.108383 DBG rpc_client.py:293 Gathering logs from all nodes
2019-03-04 09:55:45.116765 DBG scheduler.py:214 Gathering logs from all nodes
2019-03-04 09:55:50.124234 INFO gflags_handler.py:79 Generated binary file
Traceback (most recent call last):
  File "./random_traceback.py", line 113, in get_random_error_string
  File "./random_traceback.py", line 92, in get_attributes
MissingAttributeError: Extra attribute needed
2019-03-04 09:56:06.147865 DBG fanout.py:52 Fanning out RPC
2019-03-04 09:56:10.154109 INFO alert_manager.py:31 Node destroyed
2019-03-04 09:56:13.158488 DBG publisher.py:265 Creating task
2019-03-04 09:56:18.164619 INFO rpc_client.py:336 Combining logs from all nodes into single log file
2019-03-04 09:56:20.167659 INFO log_collector.py:95 Gathering node data
2019-03-04 09:56:27.176035 ERROR audit_logger.py:192 Gathering node data
2019-03-04 09:56:36.186801 ERROR publisher.py:123 Node destroyed
2019-03-04 09:56:46.198234 ERROR http_handler.py:366 Fanning out RPC
2019-03-04 09:56:52.205482 ERROR ssh_tunnel.py:366 Fanning out RPC
2019-03-04 09:56:54.208524 DBG gflags_handler.py:145 Creating task
2019-03-04 09:57:17.237506 DBG db_write.py:12 Fanning out RPC
2019-03-04 09:57:24.247197 ERROR wsgi_handler.py:380 Node created
2019-03-04 09:57:34.259039 INFO http_handler.py:283 Gathering logs from all nodes
2019-03-04 09:57:36.262453 ERROR publisher.py:312 Fanning out RPC
2019-03-04 09:57:37.263215 INFO db_read.py:126 Gathering node data
2019-03-04 09:57:39.265000 ERROR audit_logger.py:189 Generated binary file
2019-03-04 09:57:42.268268 DBG audit_logger.py:256 Generated binary file
2019-03-04 09:57:45.272801 ERROR publisher.py:297 Creating task
2019-03-04 09:57:46.274294 ERROR scheduler.py:358 Combining logs from all nodes into single log file
2019-03-04 09:57:49.278131 ERROR ssh_tunnel.py:347 Fanning out RPC
2019-03-04 09:58:04.296198 DBG fanout.py:148 Creating task
2019-03-04 09:58:07.298945 INFO rpc_client.py:9 Gathering logs from all nodes
Traceback (most recent call last):
  File "./random_traceback.py", line 98, in get_random_error_string
  File "./random_traceback.py", line 59, in get_data
BadRequestError: Request buffer too large
2019-03-04 09:58:24.317276 INFO http_handler.py:151 Node destroyed
2019-03-04 09:58:25.318576 INFO publisher.py:170 Gathering node data
2019-03-04 09:58:26.319018 ERROR scheduler.py:328 Gathering node data
2019-03-04 09:58:37.332923 ERROR scheduler.py:14 Node destroyed
2019-03-04 09:58:41.337743 INFO wsgi_handler.py:320 Creating task
2019-03-04 09:58:53.352309 DBG fanout.py:8 Gathering logs from all nodes
2019-03-04 09:58:54.353623 ERROR http_handler.py:339 Node destroyed
2019-03-04 09:59:01.362252 ERROR protobuf_parser.py:154 Node created
2019-03-04 09:59:03.364500 ERROR db_write.py:317 Node created
2019-03-04 09:59:06.368356 DBG fanout.py:178 Creating task
2019-03-04 09:59:23.389695 INFO ssh_tunnel.py:244 Generated binary file
2019-03-04 09:59:26.393620 DBG log_collector.py:320 Creating task
2019-03-04 09:59:27.395030 DBG db_read.py:54 Node destroyed
2019-03-04 09:59:28.396232 INFO scheduler.py:165 Fanning out RPC
2019-03-04 09:59:32.401507 DBG db_read.py:208 Creating task
2019-03-04 09:59:33.402768 ERROR task_generator.py:138 Generated binary file
2019-03-04 09:59:34.403896 DBG task_generator.py:285 Combining logs from all nodes into single log file
2019-03-04 09:59:39.410404 DBG log_collector.py:53 Gathering node data
2019-03-04 09:59:41.413027 INFO protobuf_parser.py:80 Gathering logs from all nodes
2019-03-04 09:59:43.415657 INFO log_collector.py:293 Fanning out RPC
2019-03-04 09:59:44.416942 ERROR protobuf_parser.py:2 Gathering logs from all nodes
2019-03-04 09:59:51.425557 ERROR protobuf_parser.py:81 Generated binary file
2019-03-04 09:59:52.426869 INFO wsgi_handler.py:146 Combining logs from all nodes into single log file
2019-03-04 09:59:53.428217 INFO fanout.py:224 Fanning out RPC
2019-03-04 09:59:57.433507 ERROR alert_manager.py:19 Node destroyed
2019-03-04 09:59:59.436128 INFO protobuf_parser.py:65 Gathering node data
2019-03-04 10:00:02.440117 DBG http_handler.py:168 Node destroyed
2019-03-04 10:00:03.441442 DBG audit_logger.py:6 Generated binary file
2019-03-04 10:00:05.442959 ERROR audit_logger.py:390 Node destroyed
2019-03-04 10:00:16.456803 ERROR ssh_tunnel.py:120 Gathering node data
2019-03-04 10:00:18.459455 DBG db_write.py:339 Gathering logs from all nodes
2019-03-04 10:00:22.464699 DBG protobuf_parser.py:249 Combining logs from all nodes into single log file
2019-03-04 10:00:23.465996 ERROR publisher.py:382 Generated binary file
2019-03-04 10:00:25.468615 INFO audit_logger.py:244 Node created
2019-03-04 10:00:27.471171 DBG gflags_handler.py:331 Creating task
2019-03-04 10:00:29.473705 DBG log_collector.py:274 Gathering logs from all nodes
2019-03-04 10:00:31.476274 ERROR ssh_tunnel.py:132 Generated binary file
2019-03-04 10:00:42.490616 DBG audit_logger.py:380 Creating task
Traceback (most recent call last):
  File "./random_traceback.py", line 108, in get_random_error_string
  File "./random_traceback.py", line 77, in return_output
  File "./random_traceback.py", line 55, in get_data
  File "./random_traceback.py", line 77, in return_output
  File "./random_traceback.py", line 59, in get_data
BasicAuthRequiredError: Password not provided
2019-03-04 10:01:07.522800 DBG audit_logger.py:228 Gathering node data
2019-03-04 10:01:13.530795 DBG fanout.py:328 Node created
2019-03-04 10:01:16.534703 ERROR ssh_tunnel.py:375 Node destroyed
2019-03-04 10:01:24.545011 INFO fanout.py:318 Node created
2019-03-04 10:01:28.550150 DBG alert_manager.py:327 Node created
Traceback (most recent call last):
  File "./random_traceback.py", line 108, in get_random_error_string
  File "./random_traceback.py", line 81, in return_output
InvalidArgumentError: Provided too many arguments
Traceback (most recent call last):
  File "./random_traceback.py", line 103, in get_random_error_string
  File "./random_traceback.py", line 66, in extract_metadata
  File "./random_traceback.py", line 75, in return_output
  File "./random_traceback.py", line 70, in extract_metadata
BadRequestError: Special Characters not allowed
2019-03-04 10:01:43.569720 DBG scheduler.py:252 Generated binary file
2019-03-04 10:01:44.571006 INFO task_generator.py:75 Generated binary file
2019-03-04 10:01:45.572327 ERROR fanout.py:271 Node created
2019-03-04 10:01:51.580165 INFO protobuf_parser.py:149 Generated binary file
2019-03-04 10:02:01.593081 ERROR task_generator.py:185 Creating task
Traceback (most recent call last):
  File "./random_traceback.py", line 113, in get_random_error_string
  File "./random_traceback.py", line 92, in get_attributes
BadRequestError: Request buffer too small
2019-03-04 10:02:10.606505 DBG publisher.py:286 Gathering logs from all nodes
Traceback (most recent call last):
  File "./random_traceback.py", line 98, in get_random_error_string
  File "./random_traceback.py", line 59, in get_data
BadRequestError: Request buffer too small
2019-03-04 10:02:22.621504 INFO fanout.py:196 Node created
2019-03-04 10:02:29.631617 ERROR ssh_tunnel.py:139 Node destroyed
2019-03-04 10:02:32.635407 INFO scheduler.py:274 Creating task
2019-03-04 10:02:40.646759 ERROR ssh_tunnel.py:2 Gathering logs from all nodes
2019-03-04 10:02:42.650124 ERROR alert_manager.py:225 Fanning out RPC
2019-03-04 10:02:43.651687 INFO db_read.py:79 Creating task
2019-03-04 10:02:54.667767 ERROR rpc_client.py:265 Creating task
2019-03-04 10:02:55.669038 INFO audit_logger.py:304 Combining logs from all nodes into single log file
2019-03-04 10:02:57.671679 ERROR scheduler.py:61 Gathering node data
2019-03-04 10:03:02.678480 ERROR task_generator.py:359 Gathering node data
2019-03-04 10:03:05.682389 DBG ssh_tunnel.py:56 Gathering logs from all nodes
2019-03-04 10:03:27.710680 INFO db_read.py:75 Gathering node data
2019-03-04 10:03:29.712328 DBG publisher.py:249 Creating task
Traceback (most recent call last):
  File "./random_traceback.py", line 98, in get_random_error_string
  File "./random_traceback.py", line 59, in get_data
BadRequestError: Special Characters not allowed
2019-03-04 10:03:34.718913 DBG fanout.py:42 Creating task
2019-03-04 10:03:36.721453 INFO alert_manager.py:240 Node destroyed
2019-03-04 10:03:37.722763 INFO ssh_tunnel.py:255 Combining logs from all nodes into single log file
2019-03-04 10:03:40.726654 ERROR scheduler.py:211 Creating task
2019-03-04 10:03:50.739105 ERROR audit_logger.py:319 Gathering logs from all nodes
2019-03-04 10:03:53.743243 INFO log_collector.py:103 Creating task
2019-03-04 10:03:55.745646 DBG ssh_tunnel.py:144 Generated binary file
2019-03-04 10:04:02.754893 INFO publisher.py:396 Fanning out RPC
2019-03-04 10:04:07.761171 INFO task_generator.py:82 Combining logs from all nodes into single log file
2019-03-04 10:04:19.776140 DBG fanout.py:137 Gathering logs from all nodes
2019-03-04 10:04:21.778657 INFO wsgi_handler.py:218 Node created
2019-03-04 10:04:23.780586 DBG scheduler.py:283 Combining logs from all nodes into single log file
2019-03-04 10:04:27.785580 INFO alert_manager.py:289 Node created
2019-03-04 10:04:28.786792 INFO scheduler.py:291 Gathering node data
2019-03-04 10:04:36.797295 INFO publisher.py:241 Creating task
2019-03-04 10:04:58.823040 ERROR publisher.py:298 Generated binary file
2019-03-04 10:04:59.824309 DBG wsgi_handler.py:33 Creating task
2019-03-04 10:05:01.826996 DBG http_handler.py:306 Gathering logs from all nodes
2019-03-04 10:05:03.829632 DBG alert_manager.py:115 Gathering node data
2019-03-04 10:05:04.830948 ERROR task_generator.py:301 Node destroyed
2019-03-04 10:05:15.845421 DBG ssh_tunnel.py:152 Combining logs from all nodes into single log file
2019-03-04 10:05:16.846739 INFO audit_logger.py:197 Gathering node data
2019-03-04 10:05:22.854520 DBG ssh_tunnel.py:101 Gathering logs from all nodes
2019-03-04 10:05:30.864861 DBG task_generator.py:309 Node created
2019-03-04 10:05:31.866066 DBG ssh_tunnel.py:214 Generated binary file
2019-03-04 10:05:32.867387 ERROR ssh_tunnel.py:51 Gathering logs from all nodes
