2019-03-04 09:55:28.095013 INFO db_write.py:295 Creating task
2019-03-04 09:55:33.100382 DBG audit_logger.py:148 Creating task
2019-03-04 09:55:41.110940 DBG db_read.py:363 Combining logs from all nodes into single log file
2019-03-04 09:55:54.130651 DBG fanout.py:344 Combining logs from all nodes into single log file
2019-03-04 09:55:55.132535 DBG wsgi_handler.py:115 Gathering logs from all nodes
2019-03-04 09:56:01.140818 ERROR log_collector.py:18 Fanning out RPC
Traceback (most recent call last):
  File "./random_traceback.py", line 113, in get_random_error_string
  File "./random_traceback.py", line 92, in get_attributes
BasicAuthRequiredError: Username not provided
2019-03-04 09:56:03.144333 ERROR task_generator.py:283 Node created
2019-03-04 09:56:12.156714 ERROR http_handler.py:362 Fanning out RPC
2019-03-04 09:56:14.159090 INFO fanout.py:19 Node created
2019-03-04 09:56:15.160396 INFO fanout.py:192 Gathering logs from all nodes
2019-03-04 09:56:22.170167 INFO task_generator.py:36 Creating task
2019-03-04 09:56:31.180811 ERROR task_generator.py:386 Gathering node data
2019-03-04 09:56:32.182019 DBG scheduler.py:27 Gathering node data
2019-03-04 09:56:33.183163 ERROR gflags_handler.py:5 Fanning out RPC
2019-03-04 09:56:37.188087 ERROR ssh_tunnel.py:288 Node destroyed
2019-03-04 09:56:42.193304 ERROR log_collector.py:77 Combining logs from all nodes into single log file
2019-03-04 09:56:43.194558 INFO log_collector.py:276 Fanning out RPC
2019-03-04 09:56:44.195259 ERROR http_handler.py:136 Gathering logs from all nodes
2019-03-04 09:56:48.201001 ERROR log_collector.py:67 Node destroyed
2019-03-04 09:56:53.206947 ERROR audit_logger.py:345 Node destroyed
2019-03-04 09:57:01.217953 DBG protobuf_parser.py:118 Fanning out RPC
2019-03-04 09:57:06.224611 ERROR wsgi_handler.py:358 Combining logs from all nodes into single log file
2019-03-04 09:57:11.231174 INFO wsgi_handler.py:174 Gathering node data
2019-03-04 09:57:14.235009 INFO fanout.py:205 Fanning out RPC
Traceback (most recent call last):
  File "./random_traceback.py", line 108, in get_random_error_string
  File "./random_traceback.py", line 81, in return_output
MissingAttributeError: Extra attribute needed
2019-03-04 09:57:26.249975 DBG alert_manager.py:140 Fanning out RPC
2019-03-04 09:57:27.251224 DBG wsgi_handler.py:128 Generated binary file
Traceback (most recent call last):
  File "./random_traceback.py", line 98, in get_random_error_string
  File "./random_traceback.py", line 59, in get_data
ConflictError: Mismatched argumnets
2019-03-04 09:57:51.280506 DBG alert_manager.py:27 Gathering logs from all nodes
2019-03-04 09:57:55.285565 ERROR http_handler.py:203 Creating task
2019-03-04 09:57:56.286927 DBG rpc_client.py:198 Creating task
2019-03-04 09:57:57.288243 INFO fanout.py:81 Generated binary file
Traceback (most recent call last):
  File "./random_traceback.py", line 98, in get_random_error_string
  File "./random_traceback.py", line 59, in get_data
BasicAuthRequiredError: Authentication not provided
2019-03-04 09:58:03.295027 INFO db_write.py:275 Generated binary file
2019-03-04 09:58:10.302738 DBG ssh_tunnel.py:173 Fanning out RPC
2019-03-04 09:58:14.306942 INFO alert_manager.py:215 Creating task
2019-03-04 09:58:17.310345 INFO publisher.py:397 Generated binary file
2019-03-04 09:58:19.312101 DBG rpc_client.py:293 Fanning out RPC
2019-03-04 09:58:23.316098 ERROR db_write.py:130 Fanning out RPC
2019-03-04 09:58:30.324559 INFO ssh_tunnel.py:159 Creating task
2019-03-04 09:58:43.340140 INFO wsgi_handler.py:15 Combining logs from all nodes into single log file
2019-03-04 09:58:44.341412 INFO db_write.py:7 Fanning out RPC
2019-03-04 09:58:56.356270 ERROR db_read.py:379 Combining logs from all nodes into single log file
2019-03-04 09:58:57.357525 DBG ssh_tunnel.py:253 Gathering logs from all nodes
2019-03-04 09:58:58.358724 ERROR protobuf_parser.py:355 Node created
2019-03-04 09:58:59.359595 ERROR audit_logger.py:202 Combining logs from all nodes into single log file
2019-03-04 09:59:00.360933 ERROR log_collector.py:352 Fanning out RPC
2019-03-04 09:59:07.369673 DBG fanout.py:259 Node destroyed
2019-03-04 09:59:10.373796 DBG http_handler.py:38 Fanning out RPC
2019-03-04 09:59:15.380391 ERROR http_handler.py:104 Fanning out RPC
2019-03-04 09:59:20.386839 DBG fanout.py:189 Creating task
2019-03-04 09:59:22.388368 DBG scheduler.py:383 Creating task
2019-03-04 09:59:36.406413 DBG wsgi_handler.py:104 Combining logs from all nodes into single log file
2019-03-04 09:59:38.409098 ERROR db_read.py:372 Gathering node data
2019-03-04 09:59:45.418236 INFO task_generator.py:249 Node destroyed
2019-03-04 09:59:47.420296 DBG fanout.py:342 Gathering node data
2019-03-04 09:59:48.421596 INFO http_handler.py:161 Combining logs from all nodes into single log file
2019-03-04 09:59:50.424250 ERROR rpc_client.py:341 Gathering logs from all nodes
2019-03-04 09:59:55.430833 ERROR wsgi_handler.py:129 Gathering logs from all nodes
2019-03-04 09:59:56.432183 INFO fanout.py:339 Fanning out RPC
2019-03-04 10:00:04.442692 DBG task_generator.py:175 Node destroyed
2019-03-04 10:00:26.469894 INFO log_collector.py:183 Combining logs from all nodes into single log file
2019-03-04 10:00:32.477550 DBG scheduler.py:140 Node destroyed
2019-03-04 10:00:35.481430 INFO db_read.py:345 Gathering node data
2019-03-04 10:00:37.484152 INFO db_read.py:373 Node created
2019-03-04 10:00:39.486737 DBG log_collector.py:180 Gathering node data
2019-03-04 10:00:40.488052 ERROR http_handler.py:67 Node destroyed
2019-03-04 10:00:45.493606 INFO http_handler.py:68 Gathering node data
2019-03-04 10:00:57.509497 INFO gflags_handler.py:139 Creating task
2019-03-04 10:00:59.512162 INFO alert_manager.py:140 Fanning out RPC
2019-03-04 10:01:01.514955 ERROR http_handler.py:95 Node destroyed
2019-03-04 10:01:02.516299 DBG ssh_tunnel.py:88 Creating task
2019-03-04 10:01:03.517629 DBG http_handler.py:172 Node created
2019-03-04 10:01:18.537301 DBG protobuf_parser.py:364 Node created
2019-03-04 10:01:25.546299 ERROR wsgi_handler.py:302 Gathering logs from all nodes
2019-03-04 10:01:27.548868 DBG http_handler.py:202 Node destroyed
2019-03-04 10:01:34.558119 INFO alert_manager.py:328 Creating task
2019-03-04 10:01:36.560687 ERROR scheduler.py:139 Node destroyed
2019-03-04 10:01:38.563261 INFO ssh_tunnel.py:106 Node created
2019-03-04 10:01:39.564555 ERROR log_collector.py:64 Creating task
2019-03-04 10:01:40.565851 INFO log_collector.py:110 Creating task
2019-03-04 10:01:42.568437 DBG fanout.py:55 Gathering logs from all nodes
2019-03-04 10:01:48.576203 INFO publisher.py:319 Fanning out RPC
2019-03-04 10:01:50.578821 DBG http_handler.py:372 Gathering node data
2019-03-04 10:01:53.582738 INFO db_write.py:35 Node created
2019-03-04 10:01:56.586616 DBG task_generator.py:394 Gathering node data
2019-03-04 10:01:58.589217 ERROR protobuf_parser.py:26 Combining logs from all nodes into single log file
2019-03-04 10:02:02.594407 INFO http_handler.py:270 Gathering node data
2019-03-04 10:02:04.597199 ERROR db_read.py:53 Combining logs from all nodes into single log file
2019-03-04 10:02:05.598870 ERROR db_read.py:307 Combining logs from all nodes into single log file
2019-03-04 10:02:07.601943 INFO wsgi_handler.py:113 Node destroyed
2019-03-04 10:02:14.610921 DBG scheduler.py:377 Node created
2019-03-04 10:02:21.620172 INFO protobuf_parser.py:262 Node created
2019-03-04 10:02:24.624158 DBG db_read.py:229 Node destroyed
2019-03-04 10:02:26.626939 INFO scheduler.py:294 Fanning out RPC
2019-03-04 10:02:31.634151 DBG rpc_client.py:194 Creating task
Traceback (most recent call last):
  File "./random_traceback.py", line 98, in get_random_error_string
  File "./random_traceback.py", line 59, in get_data
BadRequestError: Special Characters not allowed
2019-03-04 10:02:34.638053 INFO alert_manager.py:206 Node destroyed
2019-03-04 10:02:35.639493 INFO wsgi_handler.py:344 Creating task
2019-03-04 10:02:45.654543 DBG log_collector.py:175 Gathering logs from all nodes
2019-03-04 10:02:48.659203 INFO protobuf_parser.py:19 Gathering logs from all nodes
2019-03-04 10:02:52.665205 DBG alert_manager.py:99 Gathering logs from all nodes
2019-03-04 10:03:01.677144 INFO db_read.py:245 Gathering logs from all nodes
2019-03-04 10:03:12.691453 INFO http_handler.py:279 Fanning out RPC
2019-03-04 10:03:25.708208 ERROR db_read.py:178 Node created
2019-03-04 10:03:32.716262 ERROR db_read.py:66 Gathering node data
2019-03-04 10:03:42.729287 INFO log_collector.py:327 Gathering node data
2019-03-04 10:03:45.733152 INFO ssh_tunnel.py:47 Creating task
2019-03-04 10:03:48.737031 ERROR audit_logger.py:316 Fanning out RPC
2019-03-04 10:03:49.738295 DBG http_handler.py:312 Node created
Traceback (most recent call last):
  File "./random_traceback.py", line 108, in get_random_error_string
  File "./random_traceback.py", line 81, in return_output
ConflictError: Conflicting data types
2019-03-04 10:03:54.744474 DBG db_write.py:380 Node destroyed
2019-03-04 10:04:00.752307 DBG rpc_client.py:174 Gathering node data
2019-03-04 10:04:08.762429 ERROR fanout.py:100 Generated binary file
2019-03-04 10:04:11.765397 DBG task_generator.py:365 Creating task
Traceback (most recent call last):
  File "./random_traceback.py", line 113, in get_random_error_string
  File "./random_traceback.py", line 92, in get_attributes
InvalidArgumentError: Unable to parse arguments
2019-03-04 10:04:20.777423 DBG wsgi_handler.py:336 Generated binary file
2019-03-04 10:04:29.788160 INFO ssh_tunnel.py:158 Creating task
2019-03-04 10:04:32.792063 INFO publisher.py:146 Gathering logs from all nodes
2019-03-04 10:04:33.793361 ERROR wsgi_handler.py:388 Combining logs from all nodes into single log file
2019-03-04 10:04:34.794680 INFO fanout.py:354 Creating task
2019-03-04 10:04:40.802543 DBG scheduler.py:179 Creating task
2019-03-04 10:04:42.805144 INFO alert_manager.py:156 Generated binary file
2019-03-04 10:04:43.806330 DBG log_collector.py:156 Node created
2019-03-04 10:04:44.806946 ERROR log_collector.py:66 Creating task
2019-03-04 10:04:55.818948 DBG ssh_tunnel.py:29 Node destroyed
2019-03-04 10:04:56.820269 ERROR log_collector.py:388 Node created
2019-03-04 10:05:06.833496 INFO log_collector.py:237 Gathering logs from all nodes
2019-03-04 10:05:08.836102 DBG scheduler.py:236 Node created
2019-03-04 10:05:13.842710 DBG db_write.py:394 Fanning out RPC
2019-03-04 10:05:14.844098 ERROR protobuf_parser.py:88 Node created
2019-03-04 10:05:18.849250 INFO audit_logger.py:278 Gathering logs from all nodes
2019-03-04 10:05:26.859718 DBG db_write.py:84 Node created
2019-03-04 10:05:35.871343 ERROR publisher.py:312 Creating task
