2019-03-04 09:55:29.096220 ERROR wsgi_handler.py:138 Creating task
2019-03-04 09:55:31.098537 INFO db_read.py:278 Node destroyed
Traceback (most recent call last):
  File "./random_traceback.py", line 113, in get_random_error_string
  File "./random_traceback.py", line 86, in get_attributes
  File "./random_traceback.py", line 53, in get_data
  File "./random_traceback.py", line 70, in extract_metadata
BasicAuthRequiredError: Password not provided
2019-03-04 09:55:47.119027 ERROR http_handler.py:114 Combining logs from all nodes into single log file
2019-03-04 09:55:49.122908 INFO fanout.py:257 Gathering node data
2019-03-04 09:55:51.125593 ERROR fanout.py:333 Generated binary file
2019-03-04 09:55:52.126944 ERROR fanout.py:87 Fanning out RPC
2019-03-04 09:55:57.135133 DBG task_generator.py:271 Fanning out RPC
Traceback (most recent call last):
  File "./random_traceback.py", line 113, in get_random_error_string
  File "./random_traceback.py", line 92, in get_attributes
ConflictError: Mismatched argumnets
2019-03-04 09:56:17.163153 DBG db_write.py:17 Combining logs from all nodes into single log file
2019-03-04 09:56:21.168973 ERROR rpc_client.py:48 Creating task
2019-03-04 09:56:30.179646 DBG audit_logger.py:44 Node destroyed
2019-03-04 09:56:35.185640 ERROR alert_manager.py:53 Fanning out RPC
2019-03-04 09:56:38.189324 ERROR protobuf_parser.py:191 Gathering node data
2019-03-04 09:56:39.190556 INFO log_collector.py:193 Gathering node data
2019-03-04 09:56:41.192125 DBG wsgi_handler.py:70 Combining logs from all nodes into single log file
2019-03-04 09:56:56.211238 DBG alert_manager.py:181 Node destroyed
Traceback (most recent call last):
  File "./random_traceback.py", line 113, in get_random_error_string
  File "./random_traceback.py", line 92, in get_attributes
ConflictError: Mismatched argumnets
2019-03-04 09:57:04.221930 INFO ssh_tunnel.py:180 Combining logs from all nodes into single log file
2019-03-04 09:57:16.236742 DBG rpc_client.py:132 Combining logs from all nodes into single log file
2019-03-04 09:57:22.244438 DBG audit_logger.py:37 Node created
2019-03-04 09:57:29.254080 DBG rpc_client.py:261 Gathering logs from all nodes
2019-03-04 09:57:32.257279 INFO http_handler.py:145 Creating task
2019-03-04 09:57:33.257533 INFO task_generator.py:89 Node destroyed
2019-03-04 09:57:40.266275 ERROR db_write.py:97 Fanning out RPC
2019-03-04 09:57:58.289495 ERROR fanout.py:69 Creating task
2019-03-04 09:57:59.290823 ERROR alert_manager.py:56 Node created
2019-03-04 09:58:02.294524 DBG db_write.py:175 Gathering logs from all nodes
2019-03-04 09:58:05.297580 INFO db_read.py:397 Node destroyed
2019-03-04 09:58:18.310991 ERROR fanout.py:282 Gathering node data
2019-03-04 09:58:20.313258 INFO http_handler.py:335 Generated binary file
Traceback (most recent call last):
  File "./random_traceback.py", line 103, in get_random_error_string
  File "./random_traceback.py", line 70, in extract_metadata
BasicAuthRequiredError: Authentication not provided
2019-03-04 09:58:32.326921 INFO http_handler.py:31 Gathering logs from all nodes
2019-03-04 09:58:33.328264 INFO publisher.py:166 Gathering logs from all nodes
2019-03-04 09:58:35.330644 ERROR db_read.py:169 Node created
2019-03-04 09:58:42.338797 DBG publisher.py:146 Gathering node data
2019-03-04 09:58:48.345807 ERROR publisher.py:43 Gathering logs from all nodes
Traceback (most recent call last):
  File "./random_traceback.py", line 108, in get_random_error_string
  File "./random_traceback.py", line 81, in return_output
ConflictError: Data structure not supported
2019-03-04 09:58:52.351026 DBG http_handler.py:295 Gathering logs from all nodes
2019-03-04 09:59:13.377752 DBG gflags_handler.py:33 Creating task
2019-03-04 09:59:14.379072 ERROR ssh_tunnel.py:323 Gathering node data
2019-03-04 09:59:21.387019 ERROR gflags_handler.py:122 Gathering logs from all nodes
2019-03-04 09:59:25.392322 INFO rpc_client.py:52 Creating task
2019-03-04 09:59:31.400182 ERROR publisher.py:243 Creating task
2019-03-04 09:59:35.405094 ERROR audit_logger.py:268 Fanning out RPC
2019-03-04 09:59:37.407739 DBG http_handler.py:355 Fanning out RPC
2019-03-04 09:59:40.411712 ERROR alert_manager.py:87 Fanning out RPC
2019-03-04 09:59:42.414339 ERROR rpc_client.py:205 Node destroyed
2019-03-04 09:59:54.429518 DBG scheduler.py:145 Creating task
2019-03-04 10:00:01.438784 DBG db_write.py:275 Gathering logs from all nodes
2019-03-04 10:00:07.445255 DBG task_generator.py:9 Gathering node data
2019-03-04 10:00:08.446446 ERROR db_read.py:129 Fanning out RPC
2019-03-04 10:00:09.447777 INFO log_collector.py:38 Generated binary file
2019-03-04 10:00:24.467306 DBG fanout.py:186 Fanning out RPC
2019-03-04 10:00:34.480139 DBG gflags_handler.py:59 Node created
2019-03-04 10:00:38.485446 DBG rpc_client.py:39 Gathering node data
2019-03-04 10:00:41.489327 DBG publisher.py:376 Node destroyed
2019-03-04 10:00:46.494925 ERROR publisher.py:59 Fanning out RPC
2019-03-04 10:00:48.497542 INFO scheduler.py:39 Node created
Traceback (most recent call last):
  File "./random_traceback.py", line 103, in get_random_error_string
  File "./random_traceback.py", line 70, in extract_metadata
MissingAttributeError: Extra attribute needed
2019-03-04 10:00:54.505696 INFO publisher.py:284 Generated binary file
2019-03-04 10:00:58.510819 DBG protobuf_parser.py:19 Gathering logs from all nodes
2019-03-04 10:01:05.520223 ERROR alert_manager.py:5 Creating task
2019-03-04 10:01:06.521519 DBG publisher.py:273 Creating task
2019-03-04 10:01:10.526692 ERROR http_handler.py:162 Combining logs from all nodes into single log file
2019-03-04 10:01:14.532118 INFO task_generator.py:36 Node created
2019-03-04 10:01:15.533423 ERROR task_generator.py:113 Gathering logs from all nodes
2019-03-04 10:01:21.541162 DBG audit_logger.py:22 Generated binary file
2019-03-04 10:01:26.547575 DBG rpc_client.py:387 Node destroyed
2019-03-04 10:01:35.559396 INFO alert_manager.py:179 Fanning out RPC
2019-03-04 10:01:46.573617 DBG gflags_handler.py:247 Combining logs from all nodes into single log file
2019-03-04 10:01:47.574937 INFO db_read.py:87 Gathering logs from all nodes
2019-03-04 10:01:54.584040 ERROR audit_logger.py:356 Gathering node data
2019-03-04 10:02:00.591864 INFO audit_logger.py:267 Fanning out RPC
2019-03-04 10:02:09.605027 DBG log_collector.py:69 Fanning out RPC
2019-03-04 10:02:11.606999 ERROR db_write.py:168 Creating task
2019-03-04 10:02:16.613695 INFO alert_manager.py:29 Gathering logs from all nodes
2019-03-04 10:02:17.614972 INFO publisher.py:111 Node destroyed
2019-03-04 10:02:19.617528 INFO audit_logger.py:21 Node destroyed
2019-03-04 10:02:25.625472 INFO log_collector.py:13 Combining logs from all nodes into single log file
2019-03-04 10:02:27.628454 ERROR scheduler.py:190 Generated binary file
2019-03-04 10:02:30.632884 DBG task_generator.py:241 Creating task
Traceback (most recent call last):
  File "./random_traceback.py", line 98, in get_random_error_string
  File "./random_traceback.py", line 55, in get_data
  File "./random_traceback.py", line 81, in return_output
BadRequestError: Request buffer too large
2019-03-04 10:02:38.643819 INFO scheduler.py:134 Node destroyed
2019-03-04 10:02:39.645412 ERROR log_collector.py:64 Gathering logs from all nodes
2019-03-04 10:02:41.648250 INFO log_collector.py:78 Generated binary file
2019-03-04 10:02:53.666490 ERROR rpc_client.py:383 Combining logs from all nodes into single log file
Traceback (most recent call last):
  File "./random_traceback.py", line 103, in get_random_error_string
  File "./random_traceback.py", line 70, in extract_metadata
InvalidArgumentError: Arguments not supported
2019-03-04 10:02:58.672943 INFO log_collector.py:176 Gathering node data
2019-03-04 10:03:14.694297 ERROR alert_manager.py:142 Fanning out RPC
2019-03-04 10:03:15.695797 ERROR rpc_client.py:54 Gathering node data
2019-03-04 10:03:19.700784 INFO audit_logger.py:245 Combining logs from all nodes into single log file
2019-03-04 10:03:20.702043 INFO ssh_tunnel.py:378 Creating task
2019-03-04 10:03:21.703295 INFO rpc_client.py:380 Gathering logs from all nodes
Traceback (most recent call last):
  File "./random_traceback.py", line 98, in get_random_error_string
  File "./random_traceback.py", line 59, in get_data
ConflictError: Mismatched argumnets
2019-03-04 10:03:30.713689 DBG alert_manager.py:166 Generated binary file
2019-03-04 10:03:35.720169 INFO log_collector.py:276 Creating task
2019-03-04 10:03:46.734469 INFO task_generator.py:27 Gathering node data
Traceback (most recent call last):
  File "./random_traceback.py", line 103, in get_random_error_string
  File "./random_traceback.py", line 70, in extract_metadata
BadRequestError: Request buffer too large
2019-03-04 10:04:15.770933 ERROR db_write.py:373 Node destroyed
2019-03-04 10:04:16.772249 INFO wsgi_handler.py:270 Combining logs from all nodes into single log file
Traceback (most recent call last):
  File "./random_traceback.py", line 108, in get_random_error_string
  File "./random_traceback.py", line 75, in return_output
  File "./random_traceback.py", line 70, in extract_metadata
BadRequestError: Request buffer too small
2019-03-04 10:04:26.784234 ERROR db_write.py:227 Node created
2019-03-04 10:04:39.801239 ERROR scheduler.py:236 Node destroyed
2019-03-04 10:04:47.809470 INFO db_read.py:252 Node destroyed
2019-03-04 10:04:48.810807 DBG audit_logger.py:47 Gathering node data
Traceback (most recent call last):
  File "./random_traceback.py", line 103, in get_random_error_string
  File "./random_traceback.py", line 64, in extract_metadata
  File "./random_traceback.py", line 88, in get_attributes
  File "./random_traceback.py", line 92, in get_attributes
ConflictError: Mismatched argumnets
Traceback (most recent call last):
  File "./random_traceback.py", line 108, in get_random_error_string
  File "./random_traceback.py", line 81, in return_output
BasicAuthRequiredError: Invalid authentication
Traceback (most recent call last):
  File "./random_traceback.py", line 103, in get_random_error_string
  File "./random_traceback.py", line 70, in extract_metadata
InvalidArgumentError: Arguments not supported
2019-03-04 10:05:05.832275 ERROR audit_logger.py:323 Node destroyed
2019-03-04 10:05:07.834800 INFO wsgi_handler.py:275 Combining logs from all nodes into single log file
2019-03-04 10:05:19.850578 ERROR rpc_client.py:325 Creating task
2019-03-04 10:05:21.853204 INFO alert_manager.py:251 Node created
2019-03-04 10:05:25.858407 INFO audit_logger.py:66 Generated binary file
2019-03-04 10:05:34.870020 ERROR publisher.py:46 Combining logs from all nodes into single log file
