2019-03-04 09:55:21.085999 INFO audit_logger.py:200 Gathering logs from all nodes
2019-03-04 09:55:23.088450 ERROR protobuf_parser.py:251 Node created
Traceback (most recent call last):
  File "./random_traceback.py", line 103, in get_random_error_string
  File "./random_traceback.py", line 70, in extract_metadata
MissingAttributeError: Extra attribute needed
2019-03-04 09:55:25.091215 ERROR db_read.py:33 Node created
Traceback (most recent call last):
  File "./random_traceback.py", line 108, in get_random_error_string
  File "./random_traceback.py", line 75, in return_output
  File "./random_traceback.py", line 70, in extract_metadata
MissingAttributeError: Extra attribute needed
2019-03-04 09:55:30.097400 DBG fanout.py:367 Node destroyed
2019-03-04 09:55:40.109912 DBG protobuf_parser.py:309 Generated binary file
2019-03-04 09:55:43.114137 DBG wsgi_handler.py:49 Node created
2019-03-04 09:55:44.115231 DBG protobuf_parser.py:62 Combining logs from all nodes into single log file
2019-03-04 09:55:48.121124 INFO audit_logger.py:329 Gathering logs from all nodes
Traceback (most recent call last):
  File "./random_traceback.py", line 113, in get_random_error_string
  File "./random_traceback.py", line 92, in get_attributes
MissingAttributeError: Attribute missing
2019-03-04 09:55:56.134430 DBG fanout.py:368 Gathering logs from all nodes
2019-03-04 09:55:58.136622 DBG gflags_handler.py:29 Node created
2019-03-04 09:55:59.138266 INFO db_write.py:225 Combining logs from all nodes into single log file
2019-03-04 09:56:00.139396 ERROR db_write.py:95 Node created
2019-03-04 09:56:08.151406 DBG log_collector.py:356 Generated binary file
2019-03-04 09:56:09.152849 DBG scheduler.py:392 Generated binary file
2019-03-04 09:56:11.155190 ERROR publisher.py:285 Creating task
2019-03-04 09:56:19.166031 ERROR db_write.py:311 Combining logs from all nodes into single log file
2019-03-04 09:56:24.172251 DBG task_generator.py:194 Gathering logs from all nodes
2019-03-04 09:56:26.174786 ERROR ssh_tunnel.py:231 Fanning out RPC
2019-03-04 09:56:28.177229 ERROR ssh_tunnel.py:125 Node destroyed
2019-03-04 09:56:29.178422 INFO task_generator.py:216 Fanning out RPC
2019-03-04 09:56:34.184370 ERROR log_collector.py:2 Node created
2019-03-04 09:56:45.196775 ERROR log_collector.py:136 Combining logs from all nodes into single log file
2019-03-04 09:56:49.202278 ERROR publisher.py:97 Gathering logs from all nodes
Traceback (most recent call last):
  File "./random_traceback.py", line 103, in get_random_error_string
  File "./random_traceback.py", line 70, in extract_metadata
BadRequestError: Special Characters not allowed
Traceback (most recent call last):
  File "./random_traceback.py", line 103, in get_random_error_string
  File "./random_traceback.py", line 66, in extract_metadata
  File "./random_traceback.py", line 77, in return_output
  File "./random_traceback.py", line 59, in get_data
BadRequestError: Request buffer too small
2019-03-04 09:57:08.227153 DBG fanout.py:308 Node created
2019-03-04 09:57:10.230053 INFO publisher.py:152 Node destroyed
Traceback (most recent call last):
  File "./random_traceback.py", line 108, in get_random_error_string
  File "./random_traceback.py", line 81, in return_output
MissingAttributeError: Attribute not provided
2019-03-04 09:57:15.236178 INFO fanout.py:116 Creating task
2019-03-04 09:57:18.238858 INFO protobuf_parser.py:206 Generated binary file
2019-03-04 09:57:21.243218 ERROR rpc_client.py:228 Node created
2019-03-04 09:57:30.254944 ERROR scheduler.py:368 Gathering logs from all nodes
2019-03-04 09:57:31.256095 INFO alert_manager.py:347 Gathering logs from all nodes
2019-03-04 09:57:38.263921 ERROR db_read.py:280 Gathering node data
2019-03-04 09:57:41.267091 INFO alert_manager.py:182 Fanning out RPC
2019-03-04 09:57:44.271372 INFO protobuf_parser.py:1 Node created
2019-03-04 09:57:47.275362 DBG fanout.py:270 Gathering logs from all nodes
2019-03-04 09:57:48.276839 INFO log_collector.py:309 Node created
2019-03-04 09:57:50.279037 ERROR ssh_tunnel.py:302 Creating task
2019-03-04 09:57:52.282186 INFO protobuf_parser.py:46 Generated binary file
2019-03-04 09:58:01.293224 DBG fanout.py:51 Generated binary file
2019-03-04 09:58:06.298459 DBG alert_manager.py:365 Gathering node data
2019-03-04 09:58:09.301596 INFO wsgi_handler.py:1 Node destroyed
2019-03-04 09:58:12.304766 DBG rpc_client.py:133 Gathering node data
2019-03-04 09:58:15.308079 INFO log_collector.py:110 Combining logs from all nodes into single log file
2019-03-04 09:58:27.320344 INFO wsgi_handler.py:221 Node destroyed
2019-03-04 09:58:28.321692 INFO fanout.py:239 Creating task
2019-03-04 09:58:31.325697 ERROR http_handler.py:14 Creating task
2019-03-04 09:58:47.344476 INFO audit_logger.py:245 Generated binary file
2019-03-04 09:58:49.346961 DBG gflags_handler.py:197 Node created
2019-03-04 09:58:51.349723 INFO protobuf_parser.py:352 Creating task
2019-03-04 09:58:55.354961 DBG http_handler.py:131 Node destroyed
2019-03-04 09:59:02.363294 INFO fanout.py:383 Gathering node data
2019-03-04 09:59:05.367046 ERROR publisher.py:57 Fanning out RPC
2019-03-04 09:59:08.371027 DBG wsgi_handler.py:270 Combining logs from all nodes into single log file
2019-03-04 09:59:16.381706 INFO gflags_handler.py:95 Fanning out RPC
2019-03-04 09:59:29.397546 ERROR db_write.py:208 Generated binary file
2019-03-04 09:59:46.419004 ERROR protobuf_parser.py:394 Fanning out RPC
2019-03-04 09:59:49.422936 ERROR http_handler.py:58 Creating task
2019-03-04 09:59:58.434823 ERROR publisher.py:262 Node destroyed
2019-03-04 10:00:11.450465 DBG rpc_client.py:279 Generated binary file
2019-03-04 10:00:13.453056 INFO http_handler.py:169 Creating task
2019-03-04 10:00:14.454355 ERROR task_generator.py:95 Node created
2019-03-04 10:00:15.455612 ERROR wsgi_handler.py:150 Generated binary file
2019-03-04 10:00:20.462134 ERROR audit_logger.py:241 Combining logs from all nodes into single log file
2019-03-04 10:00:28.472438 INFO audit_logger.py:299 Creating task
2019-03-04 10:00:47.496215 INFO audit_logger.py:169 Gathering node data
2019-03-04 10:00:49.498896 ERROR ssh_tunnel.py:130 Fanning out RPC
2019-03-04 10:00:50.500224 INFO audit_logger.py:280 Fanning out RPC
2019-03-04 10:00:52.503095 ERROR wsgi_handler.py:331 Gathering node data
2019-03-04 10:00:55.506971 INFO db_read.py:32 Node destroyed
2019-03-04 10:00:56.508313 INFO audit_logger.py:134 Creating task
2019-03-04 10:01:08.524116 DBG ssh_tunnel.py:153 Node destroyed
2019-03-04 10:01:09.525415 ERROR db_read.py:207 Node created
Traceback (most recent call last):
  File "./random_traceback.py", line 103, in get_random_error_string
  File "./random_traceback.py", line 64, in extract_metadata
  File "./random_traceback.py", line 88, in get_attributes
  File "./random_traceback.py", line 86, in get_attributes
  File "./random_traceback.py", line 53, in get_data
  File "./random_traceback.py", line 64, in extract_metadata
  File "./random_traceback.py", line 88, in get_attributes
  File "./random_traceback.py", line 92, in get_attributes
BadRequestError: Malformed request
2019-03-04 10:01:17.536016 INFO protobuf_parser.py:303 Creating task
2019-03-04 10:01:19.538585 ERROR protobuf_parser.py:384 Combining logs from all nodes into single log file
2019-03-04 10:01:29.551431 ERROR wsgi_handler.py:170 Gathering node data
2019-03-04 10:01:37.561970 DBG db_read.py:174 Node created
2019-03-04 10:01:41.567140 INFO rpc_client.py:258 Node created
2019-03-04 10:01:49.577525 DBG rpc_client.py:201 Gathering node data
Traceback (most recent call last):
  File "./random_traceback.py", line 98, in get_random_error_string
  File "./random_traceback.py", line 59, in get_data
InvalidArgumentError: Unable to parse arguments
2019-03-04 10:02:12.608292 DBG wsgi_handler.py:222 Fanning out RPC
2019-03-04 10:02:18.616191 ERROR log_collector.py:336 Generated binary file
2019-03-04 10:02:23.622825 ERROR task_generator.py:130 Gathering node data
2019-03-04 10:02:36.641053 DBG protobuf_parser.py:250 Combining logs from all nodes into single log file
2019-03-04 10:02:46.656097 DBG fanout.py:385 Node destroyed
2019-03-04 10:03:00.675892 INFO task_generator.py:272 Node destroyed
2019-03-04 10:03:04.681240 INFO gflags_handler.py:175 Gathering logs from all nodes
Traceback (most recent call last):
  File "./random_traceback.py", line 113, in get_random_error_string
  File "./random_traceback.py", line 92, in get_attributes
MissingAttributeError: Attribute missing
2019-03-04 10:03:10.688889 INFO rpc_client.py:61 Node created
2019-03-04 10:03:11.690169 ERROR audit_logger.py:341 Creating task
2019-03-04 10:03:13.692982 INFO db_write.py:234 Generated binary file
2019-03-04 10:03:16.697135 DBG db_read.py:164 Gathering logs from all nodes
2019-03-04 10:03:17.698271 INFO db_write.py:204 Combining logs from all nodes into single log file
2019-03-04 10:03:18.699526 INFO log_collector.py:348 Node destroyed
2019-03-04 10:03:22.704463 INFO fanout.py:158 Node created
2019-03-04 10:03:24.706942 INFO rpc_client.py:277 Gathering node data
2019-03-04 10:03:26.709529 ERROR log_collector.py:59 Generated binary file
2019-03-04 10:03:31.714993 ERROR gflags_handler.py:268 Node destroyed
2019-03-04 10:03:39.725371 INFO task_generator.py:164 Generated binary file
2019-03-04 10:03:44.731833 ERROR publisher.py:102 Combining logs from all nodes into single log file
2019-03-04 10:03:56.746942 DBG publisher.py:400 Gathering logs from all nodes
Traceback (most recent call last):
  File "./random_traceback.py", line 108, in get_random_error_string
  File "./random_traceback.py", line 77, in return_output
  File "./random_traceback.py", line 53, in get_data
  File "./random_traceback.py", line 70, in extract_metadata
BasicAuthRequiredError: Username not provided
2019-03-04 10:03:58.749742 ERROR protobuf_parser.py:148 Node created
2019-03-04 10:03:59.751029 INFO ssh_tunnel.py:192 Node created
2019-03-04 10:04:03.756150 ERROR ssh_tunnel.py:363 Fanning out RPC
2019-03-04 10:04:04.757335 DBG publisher.py:373 Gathering node data
2019-03-04 10:04:05.758641 INFO scheduler.py:304 Fanning out RPC
2019-03-04 10:04:12.766699 DBG scheduler.py:369 Gathering node data
2019-03-04 10:04:17.773553 ERROR alert_manager.py:380 Gathering node data
2019-03-04 10:04:24.781869 ERROR rpc_client.py:159 Gathering node data
2019-03-04 10:04:25.783049 DBG wsgi_handler.py:180 Creating task
2019-03-04 10:04:35.795994 INFO publisher.py:287 Creating task
2019-03-04 10:04:38.799916 INFO task_generator.py:126 Generated binary file
2019-03-04 10:04:49.811013 ERROR db_read.py:372 Node destroyed
2019-03-04 10:04:50.812315 DBG rpc_client.py:141 Gathering logs from all nodes
2019-03-04 10:04:51.813554 DBG http_handler.py:326 Gathering node data
2019-03-04 10:04:53.816374 DBG db_read.py:123 Combining logs from all nodes into single log file
2019-03-04 10:04:54.817683 ERROR publisher.py:262 Gathering logs from all nodes
2019-03-04 10:05:09.837412 ERROR log_collector.py:344 Generated binary file
2019-03-04 10:05:23.855829 ERROR audit_logger.py:231 Node destroyed
2019-03-04 10:05:24.857118 DBG scheduler.py:79 Combining logs from all nodes into single log file
2019-03-04 10:05:27.860983 INFO db_write.py:95 Creating task
2019-03-04 10:05:28.862269 INFO db_read.py:234 Generated binary file
2019-03-04 10:05:36.872656 ERROR alert_manager.py:4 Fanning out RPC
