Traceback (most recent call last):
  File "./random_traceback.py", line 98, in get_random_error_string
  File "./random_traceback.py", line 59, in get_data
BadRequestError: Special Characters not allowed
2019-03-04 09:55:29.097050 DBG ssh_tunnel.py:289 Gathering node data
Traceback (most recent call last):
  File "./random_traceback.py", line 108, in get_random_error_string
  File "./random_traceback.py", line 81, in return_output
MissingAttributeError: Extra attribute needed
2019-03-04 09:55:42.112807 DBG audit_logger.py:310 Combining logs from all nodes into single log file
Traceback (most recent call last):
  File "./random_traceback.py", line 108, in get_random_error_string
  File "./random_traceback.py", line 81, in return_output
MissingAttributeError: Extra attribute needed
2019-03-04 09:55:52.127187 DBG rpc_client.py:360 Node created
2019-03-04 09:55:56.134180 INFO publisher.py:104 Node destroyed
2019-03-04 09:56:10.154060 INFO db_write.py:154 Node destroyed
2019-03-04 09:56:14.159009 INFO task_generator.py:323 Node destroyed
2019-03-04 09:56:15.160483 INFO fanout.py:92 Gathering logs from all nodes
Traceback (most recent call last):
  File "./random_traceback.py", line 103, in get_random_error_string
  File "./random_traceback.py", line 70, in extract_metadata
ConflictError: Data structure not supported
2019-03-04 09:56:24.172121 INFO fanout.py:331 Node created
2019-03-04 09:56:25.173407 INFO scheduler.py:260 Combining logs from all nodes into single log file
2019-03-04 09:56:36.185206 DBG fanout.py:74 Fanning out RPC
2019-03-04 09:56:38.186936 DBG db_read.py:55 Node destroyed
2019-03-04 09:56:55.209790 DBG ssh_tunnel.py:18 Node created
2019-03-04 09:56:57.212594 DBG protobuf_parser.py:339 Gathering node data
2019-03-04 09:56:58.214419 DBG gflags_handler.py:333 Combining logs from all nodes into single log file
2019-03-04 09:57:00.216471 ERROR alert_manager.py:149 Gathering node data
2019-03-04 09:57:02.218977 DBG scheduler.py:102 Creating task
2019-03-04 09:57:04.222129 ERROR alert_manager.py:213 Creating task
2019-03-04 09:57:07.225518 DBG fanout.py:49 Fanning out RPC
2019-03-04 09:57:08.226716 ERROR rpc_client.py:112 Fanning out RPC
2019-03-04 09:57:12.231028 ERROR alert_manager.py:322 Generated binary file
2019-03-04 09:57:18.238790 INFO gflags_handler.py:301 Node created
2019-03-04 09:57:22.244732 DBG fanout.py:87 Fanning out RPC
2019-03-04 09:57:28.252467 DBG wsgi_handler.py:176 Node destroyed
2019-03-04 09:57:32.257605 DBG task_generator.py:308 Fanning out RPC
Traceback (most recent call last):
  File "./random_traceback.py", line 98, in get_random_error_string
  File "./random_traceback.py", line 53, in get_data
  File "./random_traceback.py", line 66, in extract_metadata
  File "./random_traceback.py", line 77, in return_output
  File "./random_traceback.py", line 55, in get_data
  File "./random_traceback.py", line 75, in return_output
  File "./random_traceback.py", line 66, in extract_metadata
  File "./random_traceback.py", line 81, in return_output
ConflictError: Data structure not supported
2019-03-04 09:57:34.260448 INFO ssh_tunnel.py:148 Combining logs from all nodes into single log file
2019-03-04 09:57:36.262952 INFO scheduler.py:313 Combining logs from all nodes into single log file
2019-03-04 09:57:39.266685 INFO db_write.py:45 Node created
2019-03-04 09:57:42.268807 INFO gflags_handler.py:43 Gathering node data
2019-03-04 09:57:49.278684 INFO db_read.py:97 Combining logs from all nodes into single log file
2019-03-04 09:57:52.283071 INFO audit_logger.py:357 Generated binary file
Traceback (most recent call last):
  File "./random_traceback.py", line 108, in get_random_error_string
  File "./random_traceback.py", line 77, in return_output
  File "./random_traceback.py", line 53, in get_data
  File "./random_traceback.py", line 66, in extract_metadata
  File "./random_traceback.py", line 81, in return_output
InvalidArgumentError: Unable to parse arguments
2019-03-04 09:58:08.318248 INFO scheduler.py:285 Node destroyed
2019-03-04 09:58:11.321768 DBG task_generator.py:79 Node destroyed
2019-03-04 09:58:18.329264 DBG publisher.py:124 Node destroyed
2019-03-04 09:58:24.335143 ERROR wsgi_handler.py:67 Gathering node data
2019-03-04 09:58:30.343201 ERROR wsgi_handler.py:357 Node created
2019-03-04 09:58:36.350742 INFO scheduler.py:203 Gathering node data
2019-03-04 09:58:37.352030 INFO publisher.py:127 Creating task
2019-03-04 09:58:38.353256 ERROR db_read.py:279 Creating task
2019-03-04 09:58:41.356462 INFO db_write.py:165 Gathering logs from all nodes
Traceback (most recent call last):
  File "./random_traceback.py", line 108, in get_random_error_string
  File "./random_traceback.py", line 81, in return_output
BadRequestError: Malformed request
2019-03-04 09:58:58.378290 DBG rpc_client.py:180 Fanning out RPC
2019-03-04 09:59:05.386173 INFO db_write.py:270 Node created
2019-03-04 09:59:07.388693 INFO wsgi_handler.py:356 Generated binary file
2019-03-04 09:59:09.391147 ERROR db_read.py:263 Node created
2019-03-04 09:59:11.393874 DBG ssh_tunnel.py:94 Generated binary file
2019-03-04 09:59:13.396416 DBG alert_manager.py:175 Combining logs from all nodes into single log file
2019-03-04 09:59:16.400210 INFO db_read.py:178 Node destroyed
2019-03-04 09:59:19.404001 ERROR db_write.py:358 Creating task
2019-03-04 09:59:24.410100 ERROR db_write.py:198 Fanning out RPC
2019-03-04 09:59:25.411116 ERROR log_collector.py:74 Node destroyed
2019-03-04 09:59:26.412513 ERROR protobuf_parser.py:338 Gathering logs from all nodes
2019-03-04 09:59:29.416441 ERROR log_collector.py:171 Fanning out RPC
2019-03-04 09:59:36.424247 INFO alert_manager.py:49 Gathering node data
2019-03-04 09:59:51.443012 INFO alert_manager.py:150 Fanning out RPC
2019-03-04 09:59:53.445568 INFO log_collector.py:137 Gathering logs from all nodes
2019-03-04 10:00:04.458939 ERROR fanout.py:241 Node created
2019-03-04 10:00:09.464222 ERROR rpc_client.py:86 Creating task
2019-03-04 10:00:10.465485 INFO db_read.py:27 Generated binary file
2019-03-04 10:00:16.471916 ERROR publisher.py:95 Node created
2019-03-04 10:00:17.473179 ERROR protobuf_parser.py:14 Gathering node data
2019-03-04 10:00:23.480212 INFO scheduler.py:111 Creating task
2019-03-04 10:00:27.484421 INFO db_read.py:202 Creating task
2019-03-04 10:00:28.485684 INFO db_write.py:117 Fanning out RPC
2019-03-04 10:00:46.507970 ERROR gflags_handler.py:106 Combining logs from all nodes into single log file
2019-03-04 10:00:47.509335 INFO publisher.py:73 Creating task
2019-03-04 10:00:51.514450 INFO rpc_client.py:49 Fanning out RPC
Traceback (most recent call last):
  File "./random_traceback.py", line 108, in get_random_error_string
  File "./random_traceback.py", line 77, in return_output
  File "./random_traceback.py", line 59, in get_data
MissingAttributeError: Attribute missing
Traceback (most recent call last):
  File "./random_traceback.py", line 113, in get_random_error_string
  File "./random_traceback.py", line 88, in get_attributes
  File "./random_traceback.py", line 88, in get_attributes
  File "./random_traceback.py", line 88, in get_attributes
  File "./random_traceback.py", line 92, in get_attributes
BasicAuthRequiredError: Username not provided
2019-03-04 10:01:13.540260 INFO task_generator.py:267 Node destroyed
2019-03-04 10:01:15.542764 INFO task_generator.py:58 Generated binary file
2019-03-04 10:01:20.548264 DBG fanout.py:153 Creating task
2019-03-04 10:01:26.554986 DBG wsgi_handler.py:315 Gathering node data
2019-03-04 10:01:34.564114 ERROR ssh_tunnel.py:248 Gathering logs from all nodes
2019-03-04 10:01:37.566987 INFO scheduler.py:165 Fanning out RPC
2019-03-04 10:01:49.581422 INFO protobuf_parser.py:340 Gathering logs from all nodes
2019-03-04 10:01:51.582997 DBG publisher.py:73 Node destroyed
Traceback (most recent call last):
  File "./random_traceback.py", line 113, in get_random_error_string
  File "./random_traceback.py", line 92, in get_attributes
BadRequestError: Special Characters not allowed
2019-03-04 10:02:03.595935 ERROR db_write.py:189 Gathering logs from all nodes
2019-03-04 10:02:06.600715 ERROR audit_logger.py:67 Gathering node data
2019-03-04 10:02:20.619125 ERROR task_generator.py:354 Fanning out RPC
2019-03-04 10:02:24.624386 INFO alert_manager.py:83 Combining logs from all nodes into single log file
2019-03-04 10:02:35.639323 ERROR task_generator.py:333 Gathering logs from all nodes
2019-03-04 10:02:37.642155 INFO publisher.py:194 Creating task
2019-03-04 10:02:40.646982 DBG rpc_client.py:252 Combining logs from all nodes into single log file
Traceback (most recent call last):
  File "./random_traceback.py", line 103, in get_random_error_string
  File "./random_traceback.py", line 70, in extract_metadata
ConflictError: Data structure not supported
2019-03-04 10:03:03.678862 DBG db_read.py:65 Gathering logs from all nodes
2019-03-04 10:03:05.681368 ERROR scheduler.py:20 Gathering logs from all nodes
2019-03-04 10:03:06.682673 DBG rpc_client.py:48 Combining logs from all nodes into single log file
2019-03-04 10:03:14.693484 INFO publisher.py:355 Generated binary file
2019-03-04 10:03:17.696885 INFO protobuf_parser.py:77 Node destroyed
2019-03-04 10:03:28.711223 INFO rpc_client.py:375 Generated binary file
2019-03-04 10:03:29.712421 INFO publisher.py:327 Generated binary file
2019-03-04 10:03:31.716029 ERROR protobuf_parser.py:361 Fanning out RPC
2019-03-04 10:03:36.723388 INFO gflags_handler.py:193 Gathering node data
2019-03-04 10:03:45.735424 INFO ssh_tunnel.py:213 Node destroyed
2019-03-04 10:04:17.781920 INFO gflags_handler.py:363 Gathering logs from all nodes
2019-03-04 10:04:27.797112 ERROR scheduler.py:280 Fanning out RPC
2019-03-04 10:04:42.816120 ERROR gflags_handler.py:5 Gathering logs from all nodes
2019-03-04 10:04:43.817259 DBG scheduler.py:39 Fanning out RPC
2019-03-04 10:04:55.832405 ERROR publisher.py:352 Gathering node data
2019-03-04 10:04:59.837508 ERROR db_read.py:231 Gathering logs from all nodes
2019-03-04 10:05:02.841352 INFO fanout.py:262 Node created
2019-03-04 10:05:21.864747 ERROR fanout.py:257 Node destroyed
2019-03-04 10:05:23.867654 DBG protobuf_parser.py:367 Generated binary file
2019-03-04 10:05:25.870914 DBG wsgi_handler.py:228 Generated binary file
2019-03-04 10:05:28.875000 INFO task_generator.py:67 Node destroyed
2019-03-04 10:05:34.883587 ERROR http_handler.py:311 Gathering logs from all nodes
