Traceback (most recent call last):
  File "./random_traceback.py", line 98, in get_random_error_string
  File "./random_traceback.py", line 59, in get_data
BasicAuthRequiredError: Invalid authentication
2019-03-04 09:55:39.108173 ERROR audit_logger.py:151 Node destroyed
2019-03-04 09:55:46.118252 ERROR alert_manager.py:192 Fanning out RPC
2019-03-04 09:55:48.121295 ERROR audit_logger.py:147 Node destroyed
2019-03-04 09:55:49.122717 DBG wsgi_handler.py:100 Generated binary file
2019-03-04 09:55:54.130821 DBG protobuf_parser.py:169 Gathering logs from all nodes
2019-03-04 09:55:57.135353 ERROR publisher.py:68 Combining logs from all nodes into single log file
2019-03-04 09:55:59.138101 ERROR gflags_handler.py:315 Node destroyed
2019-03-04 09:56:00.139037 INFO alert_manager.py:75 Fanning out RPC
2019-03-04 09:56:02.142262 ERROR alert_manager.py:59 Node created
2019-03-04 09:56:07.150139 INFO gflags_handler.py:268 Combining logs from all nodes into single log file
2019-03-04 09:56:13.158039 INFO ssh_tunnel.py:262 Node destroyed
2019-03-04 09:56:17.163021 ERROR publisher.py:141 Generated binary file
2019-03-04 09:56:26.174870 ERROR rpc_client.py:5 Fanning out RPC
2019-03-04 09:56:33.182692 DBG log_collector.py:219 Creating task
2019-03-04 09:56:39.188344 DBG rpc_client.py:315 Combining logs from all nodes into single log file
2019-03-04 09:56:40.189663 ERROR scheduler.py:112 Gathering node data
2019-03-04 09:56:43.194111 INFO publisher.py:235 Combining logs from all nodes into single log file
2019-03-04 09:56:47.199224 INFO fanout.py:170 Generated binary file
2019-03-04 09:56:53.207114 ERROR http_handler.py:43 Combining logs from all nodes into single log file
Traceback (most recent call last):
  File "./random_traceback.py", line 103, in get_random_error_string
  File "./random_traceback.py", line 70, in extract_metadata
BasicAuthRequiredError: Password not provided
2019-03-04 09:57:01.218034 DBG db_read.py:299 Gathering logs from all nodes
2019-03-04 09:57:05.223029 ERROR fanout.py:5 Generated binary file
2019-03-04 09:57:11.230585 ERROR protobuf_parser.py:336 Combining logs from all nodes into single log file
2019-03-04 09:57:13.232361 INFO http_handler.py:216 Gathering logs from all nodes
2019-03-04 09:57:17.237341 INFO http_handler.py:363 Creating task
2019-03-04 09:57:19.240748 ERROR publisher.py:123 Creating task
2019-03-04 09:57:24.246975 INFO protobuf_parser.py:56 Fanning out RPC
2019-03-04 09:57:25.248839 INFO gflags_handler.py:70 Creating task
2019-03-04 09:57:27.251016 INFO db_write.py:162 Creating task
2019-03-04 09:57:35.261709 DBG rpc_client.py:193 Node destroyed
2019-03-04 09:57:40.267162 ERROR alert_manager.py:340 Gathering node data
2019-03-04 09:57:43.270037 INFO publisher.py:77 Node created
2019-03-04 09:57:47.275518 DBG audit_logger.py:167 Node created
2019-03-04 09:57:48.277172 INFO scheduler.py:276 Creating task
2019-03-04 09:57:56.288454 DBG ssh_tunnel.py:40 Fanning out RPC
2019-03-04 09:58:04.297381 DBG db_read.py:398 Generated binary file
2019-03-04 09:58:09.319068 INFO scheduler.py:98 Combining logs from all nodes into single log file
2019-03-04 09:58:12.322852 DBG ssh_tunnel.py:42 Gathering node data
2019-03-04 09:58:13.324026 ERROR http_handler.py:331 Combining logs from all nodes into single log file
2019-03-04 09:58:16.327062 ERROR wsgi_handler.py:182 Node created
2019-03-04 09:58:19.330376 INFO gflags_handler.py:304 Generated binary file
2019-03-04 09:58:23.334347 ERROR gflags_handler.py:155 Fanning out RPC
2019-03-04 09:58:33.346831 DBG rpc_client.py:352 Creating task
2019-03-04 09:58:40.355101 DBG db_write.py:365 Fanning out RPC
2019-03-04 09:58:55.375154 DBG alert_manager.py:41 Generated binary file
2019-03-04 09:58:59.379028 ERROR audit_logger.py:317 Combining logs from all nodes into single log file
2019-03-04 09:59:01.382475 ERROR protobuf_parser.py:304 Node destroyed
2019-03-04 09:59:02.383054 INFO scheduler.py:328 Node created
2019-03-04 09:59:04.384925 INFO http_handler.py:289 Node destroyed
Traceback (most recent call last):
  File "./random_traceback.py", line 113, in get_random_error_string
  File "./random_traceback.py", line 92, in get_attributes
ConflictError: Mismatched argumnets
2019-03-04 09:59:15.398951 INFO rpc_client.py:160 Generated binary file
2019-03-04 09:59:18.402727 ERROR db_write.py:210 Generated binary file
2019-03-04 09:59:21.406335 DBG log_collector.py:177 Creating task
2019-03-04 09:59:27.413921 DBG wsgi_handler.py:65 Combining logs from all nodes into single log file
2019-03-04 09:59:28.415164 ERROR rpc_client.py:25 Fanning out RPC
2019-03-04 09:59:30.417833 INFO db_write.py:101 Gathering node data
2019-03-04 09:59:33.421509 DBG audit_logger.py:89 Fanning out RPC
2019-03-04 09:59:34.421894 ERROR alert_manager.py:397 Gathering node data
2019-03-04 09:59:35.422996 DBG protobuf_parser.py:39 Combining logs from all nodes into single log file
2019-03-04 09:59:38.426750 INFO http_handler.py:1 Node destroyed
2019-03-04 09:59:40.429276 ERROR gflags_handler.py:133 Gathering logs from all nodes
2019-03-04 09:59:41.430534 DBG rpc_client.py:152 Gathering logs from all nodes
2019-03-04 09:59:44.434257 DBG publisher.py:81 Node destroyed
2019-03-04 10:00:03.458511 ERROR fanout.py:277 Fanning out RPC
2019-03-04 10:00:05.460047 ERROR gflags_handler.py:250 Fanning out RPC
2019-03-04 10:00:07.462274 INFO fanout.py:31 Node created
2019-03-04 10:00:21.477666 ERROR gflags_handler.py:56 Generated binary file
2019-03-04 10:00:25.482744 ERROR db_write.py:334 Creating task
2019-03-04 10:00:26.483155 ERROR rpc_client.py:26 Fanning out RPC
2019-03-04 10:00:31.489457 ERROR gflags_handler.py:353 Gathering logs from all nodes
2019-03-04 10:00:33.491005 ERROR scheduler.py:37 Gathering node data
2019-03-04 10:00:35.493543 ERROR fanout.py:255 Fanning out RPC
Traceback (most recent call last):
  File "./random_traceback.py", line 98, in get_random_error_string
  File "./random_traceback.py", line 55, in get_data
  File "./random_traceback.py", line 75, in return_output
  File "./random_traceback.py", line 70, in extract_metadata
ConflictError: Conflicting data types
2019-03-04 10:00:42.502792 INFO alert_manager.py:385 Node destroyed
2019-03-04 10:00:53.516146 ERROR gflags_handler.py:182 Gathering node data
2019-03-04 10:00:55.518669 INFO alert_manager.py:245 Gathering node data
2019-03-04 10:00:56.519885 ERROR publisher.py:400 Fanning out RPC
Traceback (most recent call last):
  File "./random_traceback.py", line 108, in get_random_error_string
  File "./random_traceback.py", line 81, in return_output
InvalidArgumentError: Arguments not supported
2019-03-04 10:01:05.530809 DBG alert_manager.py:199 Generated binary file
2019-03-04 10:01:06.532089 INFO publisher.py:36 Generated binary file
2019-03-04 10:01:11.537526 INFO gflags_handler.py:155 Fanning out RPC
Traceback (most recent call last):
  File "./random_traceback.py", line 103, in get_random_error_string
  File "./random_traceback.py", line 66, in extract_metadata
  File "./random_traceback.py", line 77, in return_output
  File "./random_traceback.py", line 59, in get_data
BadRequestError: Malformed request
Traceback (most recent call last):
  File "./random_traceback.py", line 98, in get_random_error_string
  File "./random_traceback.py", line 59, in get_data
BadRequestError: Request buffer too large
2019-03-04 10:01:23.552189 DBG db_write.py:69 Generated binary file
2019-03-04 10:01:24.553440 DBG ssh_tunnel.py:346 Node destroyed
2019-03-04 10:01:32.561593 DBG wsgi_handler.py:8 Gathering node data
2019-03-04 10:01:42.573492 DBG scheduler.py:75 Node destroyed
2019-03-04 10:01:48.580165 ERROR task_generator.py:391 Gathering logs from all nodes
2019-03-04 10:02:00.593514 DBG ssh_tunnel.py:177 Generated binary file
2019-03-04 10:02:05.599066 ERROR alert_manager.py:25 Creating task
2019-03-04 10:02:25.625667 DBG audit_logger.py:185 Gathering node data
2019-03-04 10:02:28.630092 DBG protobuf_parser.py:372 Combining logs from all nodes into single log file
2019-03-04 10:02:30.632294 DBG rpc_client.py:7 Creating task
Traceback (most recent call last):
  File "./random_traceback.py", line 98, in get_random_error_string
  File "./random_traceback.py", line 55, in get_data
  File "./random_traceback.py", line 77, in return_output
  File "./random_traceback.py", line 55, in get_data
  File "./random_traceback.py", line 81, in return_output
MissingAttributeError: Attribute missing
Traceback (most recent call last):
  File "./random_traceback.py", line 98, in get_random_error_string
  File "./random_traceback.py", line 59, in get_data
BadRequestError: Request buffer too large
2019-03-04 10:02:56.669661 ERROR ssh_tunnel.py:339 Combining logs from all nodes into single log file
2019-03-04 10:03:04.680196 DBG task_generator.py:393 Combining logs from all nodes into single log file
2019-03-04 10:03:07.684003 ERROR db_write.py:118 Gathering node data
2019-03-04 10:03:10.688055 ERROR ssh_tunnel.py:46 Node created
Traceback (most recent call last):
  File "./random_traceback.py", line 103, in get_random_error_string
  File "./random_traceback.py", line 64, in extract_metadata
  File "./random_traceback.py", line 92, in get_attributes
BadRequestError: Request buffer too small
2019-03-04 10:03:22.703556 INFO rpc_client.py:272 Gathering logs from all nodes
2019-03-04 10:03:24.706046 DBG protobuf_parser.py:78 Generated binary file
2019-03-04 10:03:25.707375 INFO db_write.py:223 Gathering node data
2019-03-04 10:03:37.724659 ERROR wsgi_handler.py:303 Generated binary file
2019-03-04 10:03:49.741644 DBG wsgi_handler.py:397 Creating task
2019-03-04 10:03:50.743098 INFO db_write.py:208 Gathering node data
2019-03-04 10:04:02.760293 DBG db_read.py:306 Gathering node data
2019-03-04 10:04:04.762763 INFO audit_logger.py:348 Gathering logs from all nodes
2019-03-04 10:04:08.768882 DBG alert_manager.py:289 Gathering node data
Traceback (most recent call last):
  File "./random_traceback.py", line 98, in get_random_error_string
  File "./random_traceback.py", line 59, in get_data
BasicAuthRequiredError: Username not provided
2019-03-04 10:04:14.777387 DBG audit_logger.py:328 Gathering logs from all nodes
2019-03-04 10:04:20.786268 ERROR http_handler.py:187 Gathering logs from all nodes
2019-03-04 10:04:34.806101 INFO db_read.py:390 Node destroyed
2019-03-04 10:04:37.809871 ERROR fanout.py:291 Fanning out RPC
2019-03-04 10:04:47.822166 ERROR log_collector.py:79 Creating task
2019-03-04 10:04:48.823001 INFO http_handler.py:49 Gathering node data
2019-03-04 10:04:51.826954 ERROR wsgi_handler.py:233 Creating task
2019-03-04 10:04:54.831134 DBG rpc_client.py:154 Combining logs from all nodes into single log file
2019-03-04 10:05:03.842624 DBG alert_manager.py:112 Node destroyed
2019-03-04 10:05:08.848280 DBG audit_logger.py:300 Node destroyed
2019-03-04 10:05:14.856041 ERROR gflags_handler.py:297 Gathering logs from all nodes
2019-03-04 10:05:26.872380 INFO fanout.py:178 Node destroyed
2019-03-04 10:05:29.876586 ERROR audit_logger.py:303 Gathering logs from all nodes
Traceback (most recent call last):
  File "./random_traceback.py", line 103, in get_random_error_string
  File "./random_traceback.py", line 70, in extract_metadata
BasicAuthRequiredError: Authentication not provided
2019-03-04 10:05:33.882050 ERROR http_handler.py:164 Creating task
