Traceback (most recent call last):
  File "./random_traceback.py", line 98, in get_random_error_string
  File "./random_traceback.py", line 59, in get_data
ConflictError: Conflicting data types
2019-03-04 09:55:28.095905 ERROR protobuf_parser.py:375 Generated binary file
Traceback (most recent call last):
  File "./random_traceback.py", line 108, in get_random_error_string
  File "./random_traceback.py", line 81, in return_output
BadRequestError: Malformed request
2019-03-04 09:55:37.105808 DBG audit_logger.py:289 Combining logs from all nodes into single log file
2019-03-04 09:55:41.111103 INFO scheduler.py:255 Gathering node data
2019-03-04 09:55:50.124615 ERROR gflags_handler.py:154 Node destroyed
2019-03-04 09:56:03.144489 ERROR rpc_client.py:370 Gathering node data
2019-03-04 09:56:05.147022 DBG fanout.py:186 Node created
2019-03-04 09:56:11.155011 DBG db_read.py:47 Generated binary file
2019-03-04 09:56:12.156531 INFO alert_manager.py:96 Gathering logs from all nodes
2019-03-04 09:56:18.164716 DBG rpc_client.py:8 Gathering node data
2019-03-04 09:56:19.166201 INFO alert_manager.py:151 Combining logs from all nodes into single log file
2019-03-04 09:56:27.175976 INFO ssh_tunnel.py:18 Combining logs from all nodes into single log file
2019-03-04 09:56:30.179003 DBG publisher.py:81 Node destroyed
Traceback (most recent call last):
  File "./random_traceback.py", line 113, in get_random_error_string
  File "./random_traceback.py", line 88, in get_attributes
  File "./random_traceback.py", line 86, in get_attributes
  File "./random_traceback.py", line 59, in get_data
ConflictError: Mismatched argumnets
2019-03-04 09:56:32.181499 INFO ssh_tunnel.py:297 Generated binary file
2019-03-04 09:56:34.182920 ERROR audit_logger.py:202 Gathering node data
2019-03-04 09:56:35.184093 INFO publisher.py:33 Gathering node data
2019-03-04 09:56:41.190980 DBG rpc_client.py:3 Creating task
2019-03-04 09:56:44.195447 ERROR log_collector.py:50 Combining logs from all nodes into single log file
Traceback (most recent call last):
  File "./random_traceback.py", line 103, in get_random_error_string
  File "./random_traceback.py", line 64, in extract_metadata
  File "./random_traceback.py", line 86, in get_attributes
  File "./random_traceback.py", line 59, in get_data
BasicAuthRequiredError: Invalid authentication
2019-03-04 09:56:52.206598 INFO scheduler.py:359 Gathering node data
2019-03-04 09:56:59.214943 INFO http_handler.py:224 Combining logs from all nodes into single log file
2019-03-04 09:57:06.224794 DBG db_write.py:321 Node created
2019-03-04 09:57:09.228054 ERROR log_collector.py:226 Creating task
2019-03-04 09:57:15.234915 ERROR scheduler.py:225 Gathering node data
2019-03-04 09:57:20.242190 INFO wsgi_handler.py:143 Node created
2019-03-04 09:57:29.253939 INFO fanout.py:158 Gathering node data
2019-03-04 09:57:37.264080 ERROR protobuf_parser.py:150 Gathering node data
Traceback (most recent call last):
  File "./random_traceback.py", line 108, in get_random_error_string
  File "./random_traceback.py", line 81, in return_output
ConflictError: Data structure not supported
2019-03-04 09:57:46.274134 INFO rpc_client.py:6 Node destroyed
2019-03-04 09:57:53.284370 DBG publisher.py:4 Combining logs from all nodes into single log file
2019-03-04 09:58:01.294439 ERROR rpc_client.py:6 Node destroyed
2019-03-04 09:58:02.294953 INFO db_write.py:52 Gathering node data
2019-03-04 09:58:03.296284 DBG protobuf_parser.py:244 Node created
2019-03-04 09:58:07.317062 DBG db_read.py:100 Gathering node data
2019-03-04 09:58:14.325151 INFO protobuf_parser.py:188 Fanning out RPC
2019-03-04 09:58:15.325839 ERROR protobuf_parser.py:89 Generated binary file
2019-03-04 09:58:17.328166 ERROR fanout.py:98 Gathering node data
2019-03-04 09:58:20.331025 ERROR db_read.py:45 Gathering logs from all nodes
2019-03-04 09:58:21.332019 ERROR http_handler.py:307 Gathering node data
2019-03-04 09:58:25.336602 ERROR alert_manager.py:28 Node destroyed
2019-03-04 09:58:26.337960 DBG protobuf_parser.py:372 Node destroyed
2019-03-04 09:58:32.345568 DBG protobuf_parser.py:83 Gathering logs from all nodes
2019-03-04 09:58:43.359023 INFO audit_logger.py:355 Fanning out RPC
2019-03-04 09:58:45.361700 INFO db_write.py:247 Fanning out RPC
2019-03-04 09:58:54.374036 INFO log_collector.py:179 Gathering logs from all nodes
2019-03-04 09:59:00.380657 INFO wsgi_handler.py:212 Creating task
2019-03-04 09:59:10.392433 INFO db_write.py:30 Node created
2019-03-04 09:59:17.401469 ERROR audit_logger.py:83 Gathering logs from all nodes
2019-03-04 09:59:32.420308 DBG db_read.py:249 Gathering logs from all nodes
2019-03-04 09:59:43.432990 INFO db_read.py:118 Fanning out RPC
Traceback (most recent call last):
  File "./random_traceback.py", line 103, in get_random_error_string
  File "./random_traceback.py", line 64, in extract_metadata
  File "./random_traceback.py", line 88, in get_attributes
  File "./random_traceback.py", line 86, in get_attributes
  File "./random_traceback.py", line 53, in get_data
  File "./random_traceback.py", line 70, in extract_metadata
BasicAuthRequiredError: Username not provided
2019-03-04 09:59:49.440813 ERROR alert_manager.py:242 Fanning out RPC
2019-03-04 09:59:57.450927 ERROR publisher.py:26 Fanning out RPC
2019-03-04 10:00:00.454703 ERROR task_generator.py:60 Node destroyed
2019-03-04 10:00:11.466751 DBG db_read.py:100 Gathering logs from all nodes
2019-03-04 10:00:12.467020 DBG wsgi_handler.py:106 Fanning out RPC
2019-03-04 10:00:13.468277 INFO rpc_client.py:236 Combining logs from all nodes into single log file
2019-03-04 10:00:14.469543 DBG db_write.py:78 Creating task
2019-03-04 10:00:20.476406 INFO publisher.py:57 Creating task
2019-03-04 10:00:30.488169 DBG audit_logger.py:143 Combining logs from all nodes into single log file
2019-03-04 10:00:39.498816 DBG publisher.py:1 Gathering logs from all nodes
2019-03-04 10:00:48.510478 INFO db_read.py:294 Node created
Traceback (most recent call last):
  File "./random_traceback.py", line 113, in get_random_error_string
  File "./random_traceback.py", line 88, in get_attributes
  File "./random_traceback.py", line 86, in get_attributes
  File "./random_traceback.py", line 59, in get_data
BadRequestError: Malformed request
2019-03-04 10:00:58.522448 ERROR audit_logger.py:384 Gathering logs from all nodes
2019-03-04 10:01:10.536258 DBG gflags_handler.py:26 Node created
2019-03-04 10:01:16.544039 ERROR http_handler.py:327 Creating task
2019-03-04 10:01:28.557487 ERROR db_write.py:321 Node created
2019-03-04 10:01:29.558742 INFO audit_logger.py:225 Node destroyed
Traceback (most recent call last):
  File "./random_traceback.py", line 113, in get_random_error_string
  File "./random_traceback.py", line 92, in get_attributes
InvalidArgumentError: Unable to parse arguments
2019-03-04 10:01:31.560347 DBG http_handler.py:117 Gathering logs from all nodes
2019-03-04 10:01:39.569492 ERROR alert_manager.py:284 Creating task
Traceback (most recent call last):
  File "./random_traceback.py", line 98, in get_random_error_string
  File "./random_traceback.py", line 53, in get_data
  File "./random_traceback.py", line 64, in extract_metadata
  File "./random_traceback.py", line 88, in get_attributes
  File "./random_traceback.py", line 86, in get_attributes
  File "./random_traceback.py", line 59, in get_data
BasicAuthRequiredError: Invalid authentication
2019-03-04 10:01:50.582675 ERROR gflags_handler.py:248 Fanning out RPC
2019-03-04 10:01:58.590992 DBG log_collector.py:367 Generated binary file
2019-03-04 10:02:07.602106 ERROR task_generator.py:162 Fanning out RPC
2019-03-04 10:02:12.609265 DBG log_collector.py:68 Gathering node data
2019-03-04 10:02:14.611784 ERROR wsgi_handler.py:73 Gathering logs from all nodes
2019-03-04 10:02:17.615463 ERROR http_handler.py:338 Gathering node data
2019-03-04 10:02:18.616606 DBG task_generator.py:210 Node created
2019-03-04 10:02:19.617865 DBG http_handler.py:103 Node destroyed
Traceback (most recent call last):
  File "./random_traceback.py", line 113, in get_random_error_string
  File "./random_traceback.py", line 92, in get_attributes
BasicAuthRequiredError: Username not provided
Traceback (most recent call last):
  File "./random_traceback.py", line 103, in get_random_error_string
  File "./random_traceback.py", line 70, in extract_metadata
InvalidArgumentError: Arguments not supported
2019-03-04 10:02:36.640825 ERROR publisher.py:152 Fanning out RPC
2019-03-04 10:02:49.661011 DBG log_collector.py:253 Combining logs from all nodes into single log file
2019-03-04 10:02:52.664401 DBG audit_logger.py:194 Gathering node data
2019-03-04 10:02:53.665675 DBG db_read.py:127 Gathering node data
2019-03-04 10:02:55.668375 INFO publisher.py:334 Node created
Traceback (most recent call last):
  File "./random_traceback.py", line 113, in get_random_error_string
  File "./random_traceback.py", line 88, in get_attributes
  File "./random_traceback.py", line 92, in get_attributes
ConflictError: Mismatched argumnets
2019-03-04 10:03:09.686753 ERROR protobuf_parser.py:186 Generated binary file
2019-03-04 10:03:12.690716 DBG log_collector.py:303 Gathering node data
Traceback (most recent call last):
  File "./random_traceback.py", line 98, in get_random_error_string
  File "./random_traceback.py", line 59, in get_data
InvalidArgumentError: Unable to parse arguments
2019-03-04 10:03:20.700923 INFO task_generator.py:264 Node destroyed
2019-03-04 10:03:23.704741 INFO http_handler.py:64 Creating task
2019-03-04 10:03:30.714720 ERROR fanout.py:51 Creating task
Traceback (most recent call last):
  File "./random_traceback.py", line 113, in get_random_error_string
  File "./random_traceback.py", line 92, in get_attributes
BadRequestError: Malformed request
2019-03-04 10:03:33.719103 DBG scheduler.py:316 Fanning out RPC
Traceback (most recent call last):
  File "./random_traceback.py", line 103, in get_random_error_string
  File "./random_traceback.py", line 66, in extract_metadata
  File "./random_traceback.py", line 81, in return_output
BasicAuthRequiredError: Username not provided
2019-03-04 10:03:54.748558 DBG http_handler.py:298 Fanning out RPC
2019-03-04 10:03:58.754349 ERROR publisher.py:194 Combining logs from all nodes into single log file
2019-03-04 10:03:59.755804 DBG gflags_handler.py:57 Gathering logs from all nodes
2019-03-04 10:04:19.784824 INFO alert_manager.py:174 Creating task
2019-03-04 10:04:23.790778 INFO db_write.py:315 Gathering node data
2019-03-04 10:04:25.794705 DBG protobuf_parser.py:331 Creating task
2019-03-04 10:04:32.803584 INFO publisher.py:185 Gathering logs from all nodes
2019-03-04 10:04:50.825874 INFO scheduler.py:299 Creating task
2019-03-04 10:04:57.834972 INFO rpc_client.py:42 Node destroyed
2019-03-04 10:05:00.838774 ERROR ssh_tunnel.py:376 Node destroyed
2019-03-04 10:05:04.843905 ERROR protobuf_parser.py:52 Node created
2019-03-04 10:05:13.854749 INFO scheduler.py:68 Combining logs from all nodes into single log file
2019-03-04 10:05:15.857321 DBG log_collector.py:207 Gathering node data
Traceback (most recent call last):
  File "./random_traceback.py", line 103, in get_random_error_string
  File "./random_traceback.py", line 70, in extract_metadata
ConflictError: Data structure not supported
2019-03-04 10:05:27.873676 ERROR gflags_handler.py:294 Fanning out RPC
2019-03-04 10:05:36.886474 INFO audit_logger.py:166 Generated binary file
