2019-03-04 09:55:23.088640 INFO audit_logger.py:265 Node created
2019-03-04 09:55:26.093440 INFO rpc_client.py:358 Generated binary file
2019-03-04 09:55:32.100472 DBG publisher.py:140 Node created
2019-03-04 09:55:33.101697 INFO publisher.py:31 Node destroyed
2019-03-04 09:55:40.109773 ERROR fanout.py:59 Node destroyed
2019-03-04 09:55:43.114522 ERROR rpc_client.py:303 Generated binary file
2019-03-04 09:55:53.128629 ERROR alert_manager.py:336 Node destroyed
2019-03-04 09:55:58.136819 DBG alert_manager.py:158 Generated binary file
2019-03-04 09:56:01.140627 ERROR gflags_handler.py:327 Gathering logs from all nodes
2019-03-04 09:56:04.145769 DBG log_collector.py:350 Gathering node data
2019-03-04 09:56:06.148336 ERROR ssh_tunnel.py:98 Combining logs from all nodes into single log file
2019-03-04 09:56:09.152751 INFO scheduler.py:18 Gathering logs from all nodes
2019-03-04 09:56:20.167521 DBG ssh_tunnel.py:252 Combining logs from all nodes into single log file
2019-03-04 09:56:28.177308 ERROR publisher.py:85 Node created
2019-03-04 09:56:37.186471 DBG log_collector.py:365 Generated binary file
2019-03-04 09:56:42.192551 DBG rpc_client.py:153 Creating task
2019-03-04 09:56:45.196919 ERROR rpc_client.py:6 Creating task
Traceback (most recent call last):
  File "./random_traceback.py", line 103, in get_random_error_string
  File "./random_traceback.py", line 66, in extract_metadata
  File "./random_traceback.py", line 81, in return_output
InvalidArgumentError: Unable to parse arguments
2019-03-04 09:57:16.236150 INFO http_handler.py:36 Generated binary file
2019-03-04 09:57:21.243463 DBG gflags_handler.py:357 Fanning out RPC
2019-03-04 09:57:23.245856 DBG gflags_handler.py:301 Node destroyed
2019-03-04 09:57:31.256395 INFO rpc_client.py:362 Combining logs from all nodes into single log file
2019-03-04 09:57:44.271180 DBG rpc_client.py:182 Combining logs from all nodes into single log file
2019-03-04 09:57:45.272615 DBG http_handler.py:116 Generated binary file
2019-03-04 09:57:55.286946 INFO log_collector.py:200 Creating task
2019-03-04 09:57:57.290129 ERROR fanout.py:61 Fanning out RPC
2019-03-04 09:58:06.299002 ERROR fanout.py:53 Creating task
2019-03-04 09:58:27.339196 INFO ssh_tunnel.py:76 Creating task
2019-03-04 09:58:28.340918 INFO alert_manager.py:342 Node destroyed
2019-03-04 09:58:42.357946 DBG db_write.py:161 Node destroyed
2019-03-04 09:58:47.364731 DBG http_handler.py:345 Node created
Traceback (most recent call last):
  File "./random_traceback.py", line 98, in get_random_error_string
  File "./random_traceback.py", line 53, in get_data
  File "./random_traceback.py", line 66, in extract_metadata
  File "./random_traceback.py", line 81, in return_output
MissingAttributeError: Attribute not provided
2019-03-04 09:58:50.367914 DBG rpc_client.py:345 Gathering logs from all nodes
2019-03-04 09:58:52.370862 DBG http_handler.py:51 Creating task
2019-03-04 09:58:53.372618 DBG gflags_handler.py:331 Node created
2019-03-04 09:58:56.376516 DBG log_collector.py:190 Creating task
2019-03-04 09:59:03.384163 ERROR wsgi_handler.py:259 Node created
2019-03-04 09:59:06.387431 INFO ssh_tunnel.py:392 Fanning out RPC
2019-03-04 09:59:08.389918 INFO audit_logger.py:224 Fanning out RPC
2019-03-04 09:59:14.397675 ERROR log_collector.py:219 Creating task
2019-03-04 09:59:20.405198 ERROR wsgi_handler.py:241 Gathering logs from all nodes
2019-03-04 09:59:22.407591 DBG publisher.py:51 Creating task
2019-03-04 09:59:23.408842 INFO rpc_client.py:61 Generated binary file
2019-03-04 09:59:37.425502 ERROR audit_logger.py:59 Gathering logs from all nodes
2019-03-04 09:59:39.428023 DBG wsgi_handler.py:54 Creating task
2019-03-04 09:59:42.431805 DBG ssh_tunnel.py:269 Creating task
2019-03-04 09:59:45.435525 ERROR task_generator.py:303 Creating task
2019-03-04 09:59:46.436793 ERROR db_write.py:273 Gathering node data
2019-03-04 09:59:47.438059 DBG rpc_client.py:307 Node destroyed
2019-03-04 09:59:52.444293 ERROR http_handler.py:398 Node destroyed
Traceback (most recent call last):
  File "./random_traceback.py", line 108, in get_random_error_string
  File "./random_traceback.py", line 81, in return_output
BadRequestError: Request buffer too small
2019-03-04 09:59:55.448271 INFO audit_logger.py:276 Creating task
2019-03-04 09:59:59.453446 INFO task_generator.py:10 Gathering node data
2019-03-04 10:00:06.461152 DBG audit_logger.py:329 Node destroyed
2019-03-04 10:00:08.462950 ERROR publisher.py:331 Generated binary file
2019-03-04 10:00:15.470763 INFO scheduler.py:243 Fanning out RPC
Traceback (most recent call last):
  File "./random_traceback.py", line 113, in get_random_error_string
  File "./random_traceback.py", line 86, in get_attributes
  File "./random_traceback.py", line 59, in get_data
ConflictError: Data structure not supported
2019-03-04 10:00:24.481478 DBG audit_logger.py:169 Gathering logs from all nodes
2019-03-04 10:00:34.492268 ERROR db_read.py:129 Node destroyed
2019-03-04 10:00:38.497558 DBG publisher.py:78 Combining logs from all nodes into single log file
Traceback (most recent call last):
  File "./random_traceback.py", line 113, in get_random_error_string
  File "./random_traceback.py", line 92, in get_attributes
MissingAttributeError: Attribute missing
2019-03-04 10:00:44.505443 INFO protobuf_parser.py:373 Gathering node data
2019-03-04 10:01:07.533337 ERROR gflags_handler.py:254 Gathering logs from all nodes
2019-03-04 10:01:09.535003 DBG publisher.py:150 Node created
2019-03-04 10:01:14.541509 DBG db_write.py:155 Node created
2019-03-04 10:01:19.547000 INFO db_read.py:144 Generated binary file
2019-03-04 10:01:27.556237 DBG db_write.py:132 Node created
2019-03-04 10:01:33.562838 ERROR task_generator.py:137 Generated binary file
2019-03-04 10:01:35.565367 DBG http_handler.py:362 Node destroyed
2019-03-04 10:01:36.566622 ERROR db_write.py:48 Node created
2019-03-04 10:01:38.568237 DBG wsgi_handler.py:8 Fanning out RPC
2019-03-04 10:01:43.574740 INFO protobuf_parser.py:89 Fanning out RPC
2019-03-04 10:01:44.575000 DBG audit_logger.py:21 Node destroyed
2019-03-04 10:01:53.585648 INFO ssh_tunnel.py:284 Gathering node data
2019-03-04 10:01:57.590619 INFO alert_manager.py:27 Node destroyed
2019-03-04 10:01:59.592243 ERROR scheduler.py:167 Gathering node data
2019-03-04 10:02:09.605242 ERROR gflags_handler.py:177 Creating task
2019-03-04 10:02:11.608008 DBG task_generator.py:371 Gathering logs from all nodes
2019-03-04 10:02:13.610518 ERROR alert_manager.py:239 Gathering node data
2019-03-04 10:02:21.620421 ERROR db_write.py:203 Gathering node data
2019-03-04 10:02:23.623113 DBG rpc_client.py:197 Combining logs from all nodes into single log file
2019-03-04 10:02:26.627127 DBG http_handler.py:175 Gathering node data
2019-03-04 10:02:29.630998 INFO gflags_handler.py:273 Node destroyed
2019-03-04 10:02:33.636347 DBG alert_manager.py:40 Fanning out RPC
2019-03-04 10:02:38.643986 DBG protobuf_parser.py:57 Combining logs from all nodes into single log file
2019-03-04 10:02:39.645276 DBG http_handler.py:348 Gathering node data
2019-03-04 10:02:41.648433 ERROR fanout.py:61 Node destroyed
Traceback (most recent call last):
  File "./random_traceback.py", line 98, in get_random_error_string
  File "./random_traceback.py", line 53, in get_data
  File "./random_traceback.py", line 70, in extract_metadata
MissingAttributeError: Attribute not provided
2019-03-04 10:02:43.651504 ERROR wsgi_handler.py:229 Fanning out RPC
2019-03-04 10:02:44.653205 ERROR ssh_tunnel.py:247 Node created
2019-03-04 10:02:46.656284 ERROR db_read.py:53 Node created
2019-03-04 10:02:47.657575 DBG db_read.py:220 Gathering logs from all nodes
2019-03-04 10:02:48.659071 DBG audit_logger.py:376 Combining logs from all nodes into single log file
2019-03-04 10:02:58.672248 ERROR scheduler.py:115 Gathering node data
2019-03-04 10:02:59.673527 DBG http_handler.py:321 Gathering logs from all nodes
2019-03-04 10:03:01.676288 INFO db_write.py:206 Node created
2019-03-04 10:03:02.677578 ERROR db_read.py:108 Fanning out RPC
2019-03-04 10:03:11.689392 ERROR rpc_client.py:21 Creating task
2019-03-04 10:03:16.696130 DBG fanout.py:23 Gathering node data
2019-03-04 10:03:21.702187 DBG audit_logger.py:148 Gathering node data
2019-03-04 10:03:27.709977 DBG fanout.py:15 Node created
Traceback (most recent call last):
  File "./random_traceback.py", line 103, in get_random_error_string
  File "./random_traceback.py", line 66, in extract_metadata
  File "./random_traceback.py", line 81, in return_output
BadRequestError: Request buffer too small
2019-03-04 10:03:38.725928 INFO db_write.py:85 Fanning out RPC
2019-03-04 10:03:42.731007 ERROR wsgi_handler.py:105 Combining logs from all nodes into single log file
2019-03-04 10:03:43.732293 DBG task_generator.py:254 Creating task
Traceback (most recent call last):
  File "./random_traceback.py", line 103, in get_random_error_string
  File "./random_traceback.py", line 66, in extract_metadata
  File "./random_traceback.py", line 77, in return_output
  File "./random_traceback.py", line 55, in get_data
  File "./random_traceback.py", line 77, in return_output
  File "./random_traceback.py", line 55, in get_data
  File "./random_traceback.py", line 77, in return_output
  File "./random_traceback.py", line 59, in get_data
ConflictError: Conflicting data types
2019-03-04 10:03:51.744297 ERROR db_read.py:274 Gathering node data
Traceback (most recent call last):
  File "./random_traceback.py", line 108, in get_random_error_string
  File "./random_traceback.py", line 75, in return_output
  File "./random_traceback.py", line 66, in extract_metadata
  File "./random_traceback.py", line 81, in return_output
ConflictError: Mismatched argumnets
2019-03-04 10:03:56.751079 ERROR db_read.py:216 Generated binary file
2019-03-04 10:04:00.757252 DBG task_generator.py:141 Creating task
2019-03-04 10:04:06.765806 DBG scheduler.py:186 Gathering node data
Traceback (most recent call last):
  File "./random_traceback.py", line 113, in get_random_error_string
  File "./random_traceback.py", line 92, in get_attributes
BasicAuthRequiredError: Invalid authentication
2019-03-04 10:04:11.773230 DBG audit_logger.py:229 Node destroyed
2019-03-04 10:04:15.778873 ERROR wsgi_handler.py:313 Gathering logs from all nodes
2019-03-04 10:04:18.783394 ERROR http_handler.py:227 Node destroyed
2019-03-04 10:04:22.789349 DBG alert_manager.py:301 Node destroyed
2019-03-04 10:04:24.792395 ERROR log_collector.py:223 Fanning out RPC
2019-03-04 10:04:30.801063 INFO task_generator.py:337 Fanning out RPC
2019-03-04 10:04:31.802324 ERROR audit_logger.py:118 Node created
2019-03-04 10:04:33.804839 DBG rpc_client.py:146 Gathering node data
2019-03-04 10:04:36.808618 DBG db_read.py:241 Gathering logs from all nodes
2019-03-04 10:04:38.811044 DBG log_collector.py:369 Node created
2019-03-04 10:04:39.812192 INFO fanout.py:220 Gathering node data
2019-03-04 10:04:41.814741 ERROR publisher.py:28 Combining logs from all nodes into single log file
2019-03-04 10:04:45.819828 INFO db_write.py:303 Node created
2019-03-04 10:04:46.820997 DBG db_write.py:124 Gathering logs from all nodes
2019-03-04 10:04:49.824203 DBG gflags_handler.py:20 Gathering node data
2019-03-04 10:04:56.833680 INFO gflags_handler.py:77 Node destroyed
2019-03-04 10:05:01.840082 INFO scheduler.py:179 Generated binary file
2019-03-04 10:05:06.846386 DBG ssh_tunnel.py:73 Generated binary file
2019-03-04 10:05:09.849541 ERROR fanout.py:86 Generated binary file
2019-03-04 10:05:11.852092 DBG scheduler.py:36 Node destroyed
Traceback (most recent call last):
  File "./random_traceback.py", line 108, in get_random_error_string
  File "./random_traceback.py", line 81, in return_output
MissingAttributeError: Attribute missing
2019-03-04 10:05:16.858585 ERROR alert_manager.py:189 Node destroyed
2019-03-04 10:05:17.859065 DBG audit_logger.py:192 Combining logs from all nodes into single log file
2019-03-04 10:05:18.860353 DBG log_collector.py:175 Combining logs from all nodes into single log file
2019-03-04 10:05:19.861999 DBG db_write.py:103 Fanning out RPC
2019-03-04 10:05:22.866221 ERROR db_write.py:192 Creating task
2019-03-04 10:05:30.877873 ERROR http_handler.py:110 Combining logs from all nodes into single log file
2019-03-04 10:05:31.878993 INFO rpc_client.py:187 Combining logs from all nodes into single log file
