2019-03-04 09:55:24.090161 DBG db_read.py:233 Node destroyed
2019-03-04 09:55:27.094748 INFO task_generator.py:149 Fanning out RPC
Traceback (most recent call last):
  File "./random_traceback.py", line 98, in get_random_error_string
  File "./random_traceback.py", line 59, in get_data
ConflictError: Data structure not supported
2019-03-04 09:55:35.104144 DBG protobuf_parser.py:17 Creating task
Traceback (most recent call last):
  File "./random_traceback.py", line 98, in get_random_error_string
  File "./random_traceback.py", line 55, in get_data
  File "./random_traceback.py", line 75, in return_output
  File "./random_traceback.py", line 64, in extract_metadata
  File "./random_traceback.py", line 92, in get_attributes
MissingAttributeError: Attribute not provided
2019-03-04 09:55:38.106982 INFO rpc_client.py:290 Node destroyed
2019-03-04 09:55:44.115457 DBG publisher.py:395 Generated binary file
2019-03-04 09:55:45.116939 DBG audit_logger.py:10 Fanning out RPC
Traceback (most recent call last):
  File "./random_traceback.py", line 113, in get_random_error_string
  File "./random_traceback.py", line 92, in get_attributes
ConflictError: Conflicting data types
2019-03-04 09:55:55.132732 ERROR http_handler.py:121 Combining logs from all nodes into single log file
2019-03-04 09:56:08.151030 ERROR db_read.py:396 Combining logs from all nodes into single log file
2019-03-04 09:56:16.161845 ERROR protobuf_parser.py:191 Creating task
2019-03-04 09:56:21.168905 DBG rpc_client.py:281 Fanning out RPC
2019-03-04 09:56:22.170223 INFO ssh_tunnel.py:182 Fanning out RPC
2019-03-04 09:56:29.178459 INFO db_write.py:121 Node created
2019-03-04 09:56:46.198379 INFO db_write.py:237 Fanning out RPC
2019-03-04 09:56:49.202928 INFO protobuf_parser.py:92 Node created
2019-03-04 09:56:51.205470 INFO http_handler.py:96 Combining logs from all nodes into single log file
2019-03-04 09:56:54.208464 DBG scheduler.py:129 Creating task
2019-03-04 09:57:03.220242 DBG protobuf_parser.py:15 Generated binary file
2019-03-04 09:57:10.229386 INFO wsgi_handler.py:124 Node created
Traceback (most recent call last):
  File "./random_traceback.py", line 98, in get_random_error_string
  File "./random_traceback.py", line 53, in get_data
  File "./random_traceback.py", line 70, in extract_metadata
MissingAttributeError: Attribute missing
2019-03-04 09:57:26.250029 DBG http_handler.py:98 Gathering node data
2019-03-04 09:57:30.255249 INFO wsgi_handler.py:390 Creating task
2019-03-04 09:57:41.267691 INFO ssh_tunnel.py:333 Node destroyed
2019-03-04 09:57:50.280072 ERROR protobuf_parser.py:389 Fanning out RPC
Traceback (most recent call last):
  File "./random_traceback.py", line 108, in get_random_error_string
  File "./random_traceback.py", line 81, in return_output
ConflictError: Mismatched argumnets
2019-03-04 09:57:54.285684 INFO db_read.py:369 Generated binary file
2019-03-04 09:57:58.291029 ERROR db_read.py:182 Gathering logs from all nodes
2019-03-04 09:57:59.292437 INFO publisher.py:210 Gathering node data
Traceback (most recent call last):
  File "./random_traceback.py", line 108, in get_random_error_string
  File "./random_traceback.py", line 81, in return_output
MissingAttributeError: Attribute not provided
Traceback (most recent call last):
  File "./random_traceback.py", line 108, in get_random_error_string
  File "./random_traceback.py", line 81, in return_output
MissingAttributeError: Attribute missing
2019-03-04 09:58:22.333201 INFO gflags_handler.py:361 Creating task
2019-03-04 09:58:29.342184 DBG db_write.py:259 Fanning out RPC
2019-03-04 09:58:31.344437 INFO scheduler.py:20 Fanning out RPC
Traceback (most recent call last):
  File "./random_traceback.py", line 98, in get_random_error_string
  File "./random_traceback.py", line 53, in get_data
  File "./random_traceback.py", line 70, in extract_metadata
ConflictError: Mismatched argumnets
2019-03-04 09:58:35.349486 INFO fanout.py:310 Gathering logs from all nodes
2019-03-04 09:58:39.354543 INFO task_generator.py:355 Node destroyed
2019-03-04 09:58:44.360491 DBG log_collector.py:135 Node created
2019-03-04 09:58:46.362807 ERROR log_collector.py:65 Fanning out RPC
2019-03-04 09:58:48.366141 DBG audit_logger.py:97 Generated binary file
2019-03-04 09:58:57.377693 DBG alert_manager.py:180 Creating task
2019-03-04 09:59:31.419046 DBG fanout.py:165 Generated binary file
2019-03-04 09:59:50.442075 INFO alert_manager.py:259 Gathering node data
Traceback (most recent call last):
  File "./random_traceback.py", line 98, in get_random_error_string
  File "./random_traceback.py", line 59, in get_data
ConflictError: Conflicting data types
2019-03-04 09:59:58.452183 INFO scheduler.py:131 Gathering node data
2019-03-04 10:00:01.455968 INFO db_write.py:13 Creating task
2019-03-04 10:00:02.457237 DBG ssh_tunnel.py:82 Node created
Traceback (most recent call last):
  File "./random_traceback.py", line 98, in get_random_error_string
  File "./random_traceback.py", line 59, in get_data
BasicAuthRequiredError: Invalid authentication
2019-03-04 10:00:22.478937 ERROR rpc_client.py:352 Gathering logs from all nodes
2019-03-04 10:00:29.486946 INFO ssh_tunnel.py:375 Combining logs from all nodes into single log file
2019-03-04 10:00:32.490724 DBG log_collector.py:71 Node created
2019-03-04 10:00:36.494812 ERROR protobuf_parser.py:48 Combining logs from all nodes into single log file
Traceback (most recent call last):
  File "./random_traceback.py", line 103, in get_random_error_string
  File "./random_traceback.py", line 66, in extract_metadata
  File "./random_traceback.py", line 81, in return_output
MissingAttributeError: Attribute missing
2019-03-04 10:00:41.501537 DBG db_write.py:290 Creating task
2019-03-04 10:00:45.506703 ERROR gflags_handler.py:100 Node destroyed
2019-03-04 10:00:50.513184 DBG audit_logger.py:85 Node destroyed
2019-03-04 10:00:52.514960 ERROR scheduler.py:246 Node destroyed
2019-03-04 10:00:54.517408 ERROR alert_manager.py:332 Node created
2019-03-04 10:00:59.522991 ERROR audit_logger.py:69 Generated binary file
2019-03-04 10:01:00.524258 DBG audit_logger.py:143 Gathering logs from all nodes
2019-03-04 10:01:02.526923 INFO log_collector.py:199 Creating task
Traceback (most recent call last):
  File "./random_traceback.py", line 113, in get_random_error_string
  File "./random_traceback.py", line 92, in get_attributes
ConflictError: Data structure not supported
2019-03-04 10:01:04.529559 DBG alert_manager.py:186 Gathering logs from all nodes
2019-03-04 10:01:08.534591 INFO audit_logger.py:164 Combining logs from all nodes into single log file
2019-03-04 10:01:18.546710 INFO db_write.py:223 Generated binary file
2019-03-04 10:01:21.549522 ERROR scheduler.py:171 Node destroyed
2019-03-04 10:01:25.554697 ERROR gflags_handler.py:80 Gathering logs from all nodes
2019-03-04 10:01:41.572238 ERROR protobuf_parser.py:348 Gathering node data
2019-03-04 10:01:45.576249 ERROR wsgi_handler.py:182 Gathering node data
Traceback (most recent call last):
  File "./random_traceback.py", line 113, in get_random_error_string
  File "./random_traceback.py", line 92, in get_attributes
ConflictError: Mismatched argumnets
2019-03-04 10:01:47.578916 INFO ssh_tunnel.py:303 Gathering logs from all nodes
2019-03-04 10:01:54.586934 ERROR alert_manager.py:319 Node created
2019-03-04 10:01:55.588186 INFO log_collector.py:384 Fanning out RPC
2019-03-04 10:01:56.589449 DBG audit_logger.py:70 Creating task
2019-03-04 10:02:01.594664 DBG db_write.py:370 Node destroyed
2019-03-04 10:02:02.594965 DBG db_read.py:354 Node created
Traceback (most recent call last):
  File "./random_traceback.py", line 98, in get_random_error_string
  File "./random_traceback.py", line 53, in get_data
  File "./random_traceback.py", line 64, in extract_metadata
  File "./random_traceback.py", line 86, in get_attributes
  File "./random_traceback.py", line 53, in get_data
  File "./random_traceback.py", line 66, in extract_metadata
  File "./random_traceback.py", line 75, in return_output
  File "./random_traceback.py", line 70, in extract_metadata
ConflictError: Mismatched argumnets
2019-03-04 10:02:08.603407 DBG fanout.py:248 Combining logs from all nodes into single log file
2019-03-04 10:02:10.606705 ERROR wsgi_handler.py:95 Node created
2019-03-04 10:02:15.613037 INFO ssh_tunnel.py:174 Combining logs from all nodes into single log file
2019-03-04 10:02:16.614294 ERROR protobuf_parser.py:296 Combining logs from all nodes into single log file
2019-03-04 10:02:22.621859 ERROR task_generator.py:21 Creating task
2019-03-04 10:02:31.633602 DBG ssh_tunnel.py:388 Node created
2019-03-04 10:02:45.654723 DBG http_handler.py:186 Gathering logs from all nodes
Traceback (most recent call last):
  File "./random_traceback.py", line 113, in get_random_error_string
  File "./random_traceback.py", line 92, in get_attributes
BasicAuthRequiredError: Authentication not provided
Traceback (most recent call last):
  File "./random_traceback.py", line 108, in get_random_error_string
  File "./random_traceback.py", line 81, in return_output
InvalidArgumentError: Provided too many arguments
2019-03-04 10:02:57.670964 ERROR db_read.py:398 Creating task
2019-03-04 10:03:15.694821 DBG scheduler.py:296 Node created
2019-03-04 10:03:19.699650 DBG gflags_handler.py:324 Generated binary file
Traceback (most recent call last):
  File "./random_traceback.py", line 113, in get_random_error_string
  File "./random_traceback.py", line 92, in get_attributes
BadRequestError: Request buffer too large
2019-03-04 10:03:35.722122 DBG protobuf_parser.py:344 Creating task
2019-03-04 10:03:39.727197 ERROR task_generator.py:15 Fanning out RPC
2019-03-04 10:03:40.728464 DBG http_handler.py:400 Gathering logs from all nodes
2019-03-04 10:03:41.729731 DBG publisher.py:3 Creating task
2019-03-04 10:03:47.738390 ERROR scheduler.py:92 Generated binary file
2019-03-04 10:03:48.739844 DBG wsgi_handler.py:121 Gathering logs from all nodes
2019-03-04 10:03:52.745810 ERROR wsgi_handler.py:277 Gathering logs from all nodes
2019-03-04 10:03:55.749781 INFO publisher.py:388 Fanning out RPC
Traceback (most recent call last):
  File "./random_traceback.py", line 98, in get_random_error_string
  File "./random_traceback.py", line 59, in get_data
BadRequestError: Request buffer too small
2019-03-04 10:04:01.758691 ERROR http_handler.py:75 Fanning out RPC
2019-03-04 10:04:03.761619 DBG wsgi_handler.py:15 Fanning out RPC
2019-03-04 10:04:05.764409 DBG db_write.py:58 Gathering node data
Traceback (most recent call last):
  File "./random_traceback.py", line 98, in get_random_error_string
  File "./random_traceback.py", line 55, in get_data
  File "./random_traceback.py", line 75, in return_output
  File "./random_traceback.py", line 66, in extract_metadata
  File "./random_traceback.py", line 81, in return_output
ConflictError: Conflicting data types
2019-03-04 10:04:12.774525 INFO db_read.py:108 Fanning out RPC
2019-03-04 10:04:13.776099 ERROR db_read.py:17 Node created
2019-03-04 10:04:16.780360 ERROR rpc_client.py:99 Creating task
Traceback (most recent call last):
  File "./random_traceback.py", line 113, in get_random_error_string
  File "./random_traceback.py", line 88, in get_attributes
  File "./random_traceback.py", line 92, in get_attributes
BasicAuthRequiredError: Username not provided
2019-03-04 10:04:26.795852 INFO audit_logger.py:376 Creating task
2019-03-04 10:04:28.798339 ERROR audit_logger.py:9 Gathering node data
2019-03-04 10:04:29.799597 ERROR log_collector.py:330 Fanning out RPC
2019-03-04 10:04:35.807364 DBG fanout.py:73 Node destroyed
2019-03-04 10:04:40.813470 DBG wsgi_handler.py:137 Gathering logs from all nodes
2019-03-04 10:04:44.818594 DBG db_write.py:71 Generated binary file
Traceback (most recent call last):
  File "./random_traceback.py", line 113, in get_random_error_string
  File "./random_traceback.py", line 86, in get_attributes
  File "./random_traceback.py", line 55, in get_data
  File "./random_traceback.py", line 77, in return_output
  File "./random_traceback.py", line 53, in get_data
  File "./random_traceback.py", line 66, in extract_metadata
  File "./random_traceback.py", line 75, in return_output
  File "./random_traceback.py", line 64, in extract_metadata
  File "./random_traceback.py", line 88, in get_attributes
  File "./random_traceback.py", line 88, in get_attributes
  File "./random_traceback.py", line 92, in get_attributes
MissingAttributeError: Attribute not provided
Traceback (most recent call last):
  File "./random_traceback.py", line 113, in get_random_error_string
  File "./random_traceback.py", line 92, in get_attributes
BadRequestError: Request buffer too large
2019-03-04 10:04:58.836240 INFO scheduler.py:308 Combining logs from all nodes into single log file
2019-03-04 10:05:05.845178 ERROR publisher.py:300 Node destroyed
2019-03-04 10:05:07.847009 DBG http_handler.py:111 Node created
2019-03-04 10:05:10.850808 INFO scheduler.py:203 Node destroyed
2019-03-04 10:05:20.863300 INFO task_generator.py:121 Node created
2019-03-04 10:05:35.885031 ERROR protobuf_parser.py:2 Generated binary file
