2019-03-04 09:55:32.099630 ERROR http_handler.py:170 Combining logs from all nodes into single log file
2019-03-04 09:55:38.106915 ERROR log_collector.py:64 Node destroyed
2019-03-04 09:55:39.108588 ERROR http_handler.py:376 Gathering logs from all nodes
2019-03-04 09:55:41.111222 ERROR scheduler.py:272 Gathering node data
2019-03-04 09:55:43.114335 DBG audit_logger.py:364 Node destroyed
2019-03-04 09:55:55.132360 ERROR fanout.py:357 Gathering logs from all nodes
2019-03-04 09:56:03.144111 DBG task_generator.py:362 Gathering logs from all nodes
2019-03-04 09:56:08.151241 ERROR ssh_tunnel.py:233 Fanning out RPC
2019-03-04 09:56:14.158913 INFO fanout.py:171 Gathering logs from all nodes
2019-03-04 09:56:15.160286 ERROR protobuf_parser.py:197 Combining logs from all nodes into single log file
2019-03-04 09:56:21.168345 INFO rpc_client.py:328 Node destroyed
2019-03-04 09:56:22.169578 ERROR publisher.py:304 Generated binary file
2019-03-04 09:56:26.173633 DBG scheduler.py:394 Combining logs from all nodes into single log file
2019-03-04 09:56:27.173966 ERROR rpc_client.py:91 Creating task
2019-03-04 09:56:32.180154 INFO publisher.py:340 Fanning out RPC
2019-03-04 09:56:33.181422 ERROR db_write.py:316 Gathering node data
2019-03-04 09:56:37.185462 DBG audit_logger.py:312 Fanning out RPC
2019-03-04 09:56:41.191099 DBG publisher.py:77 Gathering node data
2019-03-04 09:56:42.192309 DBG db_write.py:308 Gathering node data
2019-03-04 09:56:49.202087 ERROR alert_manager.py:54 Generated binary file
2019-03-04 09:56:53.207277 INFO audit_logger.py:388 Node destroyed
2019-03-04 09:57:02.219088 ERROR fanout.py:216 Fanning out RPC
2019-03-04 09:57:04.221750 DBG log_collector.py:43 Generated binary file
2019-03-04 09:57:12.232116 DBG ssh_tunnel.py:88 Creating task
2019-03-04 09:57:15.235541 ERROR db_read.py:345 Generated binary file
2019-03-04 09:57:20.242075 DBG rpc_client.py:141 Combining logs from all nodes into single log file
Traceback (most recent call last):
  File "./random_traceback.py", line 113, in get_random_error_string
  File "./random_traceback.py", line 86, in get_attributes
  File "./random_traceback.py", line 55, in get_data
  File "./random_traceback.py", line 77, in return_output
  File "./random_traceback.py", line 53, in get_data
  File "./random_traceback.py", line 70, in extract_metadata
ConflictError: Mismatched argumnets
2019-03-04 09:57:30.254765 INFO scheduler.py:32 Node destroyed
2019-03-04 09:57:31.255113 ERROR scheduler.py:370 Node destroyed
2019-03-04 09:57:33.257749 ERROR scheduler.py:40 Gathering logs from all nodes
Traceback (most recent call last):
  File "./random_traceback.py", line 113, in get_random_error_string
  File "./random_traceback.py", line 92, in get_attributes
MissingAttributeError: Attribute not provided
2019-03-04 09:57:35.260885 INFO db_read.py:30 Gathering node data
2019-03-04 09:57:37.262979 INFO db_read.py:339 Gathering node data
2019-03-04 09:57:42.268394 DBG http_handler.py:90 Creating task
2019-03-04 09:57:47.274931 INFO fanout.py:246 Creating task
2019-03-04 09:57:52.282950 INFO log_collector.py:341 Generated binary file
2019-03-04 09:57:54.285570 ERROR db_write.py:384 Combining logs from all nodes into single log file
2019-03-04 09:58:01.294582 INFO gflags_handler.py:348 Generated binary file
2019-03-04 09:58:05.298700 DBG alert_manager.py:198 Creating task
Traceback (most recent call last):
  File "./random_traceback.py", line 98, in get_random_error_string
  File "./random_traceback.py", line 59, in get_data
InvalidArgumentError: Unable to parse arguments
2019-03-04 09:58:16.326939 ERROR scheduler.py:379 Gathering logs from all nodes
2019-03-04 09:58:17.327688 DBG protobuf_parser.py:103 Gathering node data
2019-03-04 09:58:18.328777 DBG db_read.py:157 Node created
2019-03-04 09:58:20.330958 DBG audit_logger.py:206 Fanning out RPC
2019-03-04 09:58:24.334971 DBG task_generator.py:354 Gathering node data
2019-03-04 09:58:26.337865 INFO ssh_tunnel.py:341 Creating task
2019-03-04 09:58:28.340740 INFO wsgi_handler.py:119 Gathering node data
2019-03-04 09:58:37.350939 DBG db_write.py:344 Fanning out RPC
2019-03-04 09:58:39.353641 INFO ssh_tunnel.py:188 Gathering node data
2019-03-04 09:58:40.354925 DBG audit_logger.py:352 Fanning out RPC
2019-03-04 09:58:42.357780 DBG gflags_handler.py:247 Node created
Traceback (most recent call last):
  File "./random_traceback.py", line 103, in get_random_error_string
  File "./random_traceback.py", line 70, in extract_metadata
MissingAttributeError: Attribute not provided
2019-03-04 09:58:48.365987 INFO scheduler.py:314 Node destroyed
2019-03-04 09:58:49.367080 DBG db_write.py:250 Gathering node data
2019-03-04 09:58:51.369558 ERROR alert_manager.py:267 Generated binary file
2019-03-04 09:59:01.382269 ERROR ssh_tunnel.py:28 Node destroyed
2019-03-04 09:59:05.385557 ERROR scheduler.py:240 Creating task
Traceback (most recent call last):
  File "./random_traceback.py", line 113, in get_random_error_string
  File "./random_traceback.py", line 88, in get_attributes
  File "./random_traceback.py", line 86, in get_attributes
  File "./random_traceback.py", line 59, in get_data
MissingAttributeError: Attribute missing
2019-03-04 09:59:23.408260 ERROR task_generator.py:222 Gathering logs from all nodes
Traceback (most recent call last):
  File "./random_traceback.py", line 108, in get_random_error_string
  File "./random_traceback.py", line 75, in return_output
  File "./random_traceback.py", line 70, in extract_metadata
BadRequestError: Request buffer too large
2019-03-04 09:59:28.415001 INFO gflags_handler.py:272 Node destroyed
2019-03-04 09:59:35.423999 DBG fanout.py:166 Gathering node data
2019-03-04 09:59:36.425243 DBG wsgi_handler.py:148 Creating task
2019-03-04 09:59:38.427748 ERROR db_read.py:287 Generated binary file
2019-03-04 09:59:45.436716 INFO fanout.py:231 Fanning out RPC
Traceback (most recent call last):
  File "./random_traceback.py", line 113, in get_random_error_string
  File "./random_traceback.py", line 92, in get_attributes
MissingAttributeError: Attribute not provided
2019-03-04 09:59:59.454710 DBG scheduler.py:30 Generated binary file
2019-03-04 10:00:00.455008 INFO gflags_handler.py:6 Gathering logs from all nodes
2019-03-04 10:00:01.456285 ERROR wsgi_handler.py:336 Combining logs from all nodes into single log file
2019-03-04 10:00:02.457560 INFO alert_manager.py:384 Gathering logs from all nodes
2019-03-04 10:00:05.461183 ERROR task_generator.py:9 Gathering logs from all nodes
2019-03-04 10:00:13.470490 ERROR gflags_handler.py:245 Gathering logs from all nodes
2019-03-04 10:00:14.471761 INFO protobuf_parser.py:190 Gathering logs from all nodes
2019-03-04 10:00:18.476678 ERROR fanout.py:154 Fanning out RPC
2019-03-04 10:00:23.483019 DBG task_generator.py:73 Generated binary file
2019-03-04 10:00:29.490673 ERROR task_generator.py:200 Node destroyed
2019-03-04 10:00:32.494440 DBG ssh_tunnel.py:66 Gathering logs from all nodes
2019-03-04 10:00:33.495704 INFO alert_manager.py:323 Gathering node data
2019-03-04 10:00:36.499519 INFO log_collector.py:240 Fanning out RPC
2019-03-04 10:00:52.520117 DBG log_collector.py:36 Node destroyed
2019-03-04 10:01:06.537812 ERROR audit_logger.py:242 Generated binary file
Traceback (most recent call last):
  File "./random_traceback.py", line 98, in get_random_error_string
  File "./random_traceback.py", line 59, in get_data
BadRequestError: Malformed request
Traceback (most recent call last):
  File "./random_traceback.py", line 113, in get_random_error_string
  File "./random_traceback.py", line 88, in get_attributes
  File "./random_traceback.py", line 88, in get_attributes
  File "./random_traceback.py", line 86, in get_attributes
  File "./random_traceback.py", line 55, in get_data
  File "./random_traceback.py", line 81, in return_output
BasicAuthRequiredError: Password not provided
2019-03-04 10:01:11.544532 INFO task_generator.py:104 Creating task
2019-03-04 10:01:19.554945 ERROR fanout.py:376 Combining logs from all nodes into single log file
2019-03-04 10:01:23.560064 ERROR protobuf_parser.py:305 Combining logs from all nodes into single log file
2019-03-04 10:01:27.565300 ERROR gflags_handler.py:255 Fanning out RPC
2019-03-04 10:01:29.567865 DBG log_collector.py:262 Gathering node data
2019-03-04 10:01:33.572966 ERROR rpc_client.py:151 Fanning out RPC
2019-03-04 10:01:34.574240 ERROR alert_manager.py:232 Node created
2019-03-04 10:01:37.578058 ERROR alert_manager.py:259 Node destroyed
2019-03-04 10:01:40.582069 ERROR alert_manager.py:373 Generated binary file
2019-03-04 10:01:43.585893 DBG wsgi_handler.py:226 Gathering node data
Traceback (most recent call last):
  File "./random_traceback.py", line 98, in get_random_error_string
  File "./random_traceback.py", line 59, in get_data
InvalidArgumentError: Provided too many arguments
2019-03-04 10:01:57.603666 INFO db_write.py:363 Gathering node data
2019-03-04 10:01:58.604925 DBG fanout.py:359 Combining logs from all nodes into single log file
2019-03-04 10:01:59.606188 INFO publisher.py:239 Gathering logs from all nodes
2019-03-04 10:02:01.608196 INFO task_generator.py:285 Node destroyed
2019-03-04 10:02:16.626706 INFO alert_manager.py:365 Node created
2019-03-04 10:02:21.632958 INFO scheduler.py:304 Combining logs from all nodes into single log file
2019-03-04 10:02:28.641534 DBG ssh_tunnel.py:81 Creating task
2019-03-04 10:02:50.667959 ERROR gflags_handler.py:180 Node created
2019-03-04 10:02:51.669172 INFO log_collector.py:72 Gathering logs from all nodes
Traceback (most recent call last):
  File "./random_traceback.py", line 108, in get_random_error_string
  File "./random_traceback.py", line 81, in return_output
BasicAuthRequiredError: Username not provided
2019-03-04 10:03:00.679011 ERROR db_read.py:265 Gathering node data
2019-03-04 10:03:07.686938 DBG wsgi_handler.py:150 Combining logs from all nodes into single log file
2019-03-04 10:03:08.688202 INFO db_read.py:71 Node created
2019-03-04 10:03:10.690715 ERROR db_read.py:316 Creating task
2019-03-04 10:03:17.698682 DBG db_write.py:23 Node destroyed
2019-03-04 10:03:20.701537 ERROR protobuf_parser.py:61 Gathering logs from all nodes
2019-03-04 10:03:26.709073 ERROR gflags_handler.py:321 Generated binary file
Traceback (most recent call last):
  File "./random_traceback.py", line 108, in get_random_error_string
  File "./random_traceback.py", line 75, in return_output
  File "./random_traceback.py", line 70, in extract_metadata
BadRequestError: Malformed request
2019-03-04 10:03:40.728663 DBG wsgi_handler.py:194 Generated binary file
2019-03-04 10:03:42.731207 ERROR log_collector.py:222 Gathering node data
2019-03-04 10:03:43.732423 DBG wsgi_handler.py:19 Gathering logs from all nodes
2019-03-04 10:03:44.733973 ERROR audit_logger.py:54 Node destroyed
2019-03-04 10:03:47.738577 DBG task_generator.py:364 Node created
2019-03-04 10:03:49.741474 DBG db_write.py:323 Node created
2019-03-04 10:03:51.744158 DBG audit_logger.py:396 Creating task
2019-03-04 10:03:56.751248 INFO scheduler.py:388 Fanning out RPC
Traceback (most recent call last):
  File "./random_traceback.py", line 113, in get_random_error_string
  File "./random_traceback.py", line 92, in get_attributes
BasicAuthRequiredError: Password not provided
2019-03-04 10:04:05.764216 ERROR publisher.py:138 Fanning out RPC
2019-03-04 10:04:13.775955 INFO protobuf_parser.py:203 Combining logs from all nodes into single log file
2019-03-04 10:04:21.787852 DBG alert_manager.py:160 Fanning out RPC
2019-03-04 10:04:33.803661 INFO alert_manager.py:396 Fanning out RPC
2019-03-04 10:04:40.812316 ERROR wsgi_handler.py:84 Generated binary file
2019-03-04 10:04:43.816142 INFO wsgi_handler.py:379 Combining logs from all nodes into single log file
2019-03-04 10:04:45.818676 DBG db_read.py:165 Node created
2019-03-04 10:04:46.819851 INFO http_handler.py:107 Node created
2019-03-04 10:04:52.827163 ERROR db_write.py:116 Fanning out RPC
2019-03-04 10:04:57.833559 INFO wsgi_handler.py:332 Node destroyed
2019-03-04 10:05:02.840037 ERROR audit_logger.py:111 Node destroyed
2019-03-04 10:05:03.841293 ERROR http_handler.py:2 Gathering logs from all nodes
2019-03-04 10:05:06.845012 DBG db_read.py:257 Gathering node data
2019-03-04 10:05:08.847583 DBG alert_manager.py:23 Node created
2019-03-04 10:05:19.861838 DBG publisher.py:72 Node destroyed
2019-03-04 10:05:20.863480 ERROR task_generator.py:139 Node created
2019-03-04 10:05:26.872218 INFO audit_logger.py:112 Generated binary file
2019-03-04 10:05:29.876420 ERROR publisher.py:225 Fanning out RPC
2019-03-04 10:05:31.879156 INFO http_handler.py:383 Combining logs from all nodes into single log file
2019-03-04 10:05:32.880468 DBG db_write.py:185 Node destroyed
