2019-03-04 09:55:22.087096 ERROR scheduler.py:52 Gathering node data
2019-03-04 09:55:23.088888 INFO protobuf_parser.py:343 Gathering node data
2019-03-04 09:55:29.095889 DBG log_collector.py:177 Gathering node data
2019-03-04 09:55:34.101975 ERROR log_collector.py:29 Node destroyed
2019-03-04 09:55:45.116855 DBG alert_manager.py:158 Generated binary file
2019-03-04 09:55:46.118409 DBG task_generator.py:213 Combining logs from all nodes into single log file
2019-03-04 09:55:47.119512 INFO ssh_tunnel.py:262 Node destroyed
2019-03-04 09:55:48.120910 DBG gflags_handler.py:5 Node destroyed
2019-03-04 09:55:50.124799 DBG rpc_client.py:64 Creating task
2019-03-04 09:55:51.126360 ERROR protobuf_parser.py:72 Creating task
2019-03-04 09:56:02.142773 DBG protobuf_parser.py:155 Gathering node data
2019-03-04 09:56:10.153679 INFO publisher.py:314 Gathering logs from all nodes
2019-03-04 09:56:13.158353 DBG publisher.py:395 Gathering node data
2019-03-04 09:56:16.161697 INFO rpc_client.py:169 Combining logs from all nodes into single log file
2019-03-04 09:56:18.164526 DBG protobuf_parser.py:262 Gathering node data
2019-03-04 09:56:20.167029 ERROR log_collector.py:308 Gathering logs from all nodes
2019-03-04 09:56:38.186741 DBG gflags_handler.py:296 Creating task
2019-03-04 09:56:39.188172 ERROR audit_logger.py:329 Node created
2019-03-04 09:56:46.197856 ERROR log_collector.py:217 Fanning out RPC
2019-03-04 09:56:48.200697 ERROR wsgi_handler.py:168 Node destroyed
Traceback (most recent call last):
  File "./random_traceback.py", line 108, in get_random_error_string
  File "./random_traceback.py", line 81, in return_output
BasicAuthRequiredError: Password not provided
2019-03-04 09:56:51.204327 ERROR rpc_client.py:362 Node created
2019-03-04 09:56:56.210962 ERROR protobuf_parser.py:302 Gathering logs from all nodes
2019-03-04 09:57:01.217829 DBG scheduler.py:336 Creating task
Traceback (most recent call last):
  File "./random_traceback.py", line 108, in get_random_error_string
  File "./random_traceback.py", line 81, in return_output
ConflictError: Data structure not supported
Traceback (most recent call last):
  File "./random_traceback.py", line 113, in get_random_error_string
  File "./random_traceback.py", line 88, in get_attributes
  File "./random_traceback.py", line 86, in get_attributes
  File "./random_traceback.py", line 53, in get_data
  File "./random_traceback.py", line 64, in extract_metadata
  File "./random_traceback.py", line 86, in get_attributes
  File "./random_traceback.py", line 55, in get_data
  File "./random_traceback.py", line 77, in return_output
  File "./random_traceback.py", line 59, in get_data
InvalidArgumentError: Arguments not supported
Traceback (most recent call last):
  File "./random_traceback.py", line 98, in get_random_error_string
  File "./random_traceback.py", line 53, in get_data
  File "./random_traceback.py", line 70, in extract_metadata
ConflictError: Conflicting data types
2019-03-04 09:57:21.243043 DBG wsgi_handler.py:339 Creating task
2019-03-04 09:57:23.246062 INFO db_read.py:341 Creating task
2019-03-04 09:57:25.248260 DBG publisher.py:81 Node destroyed
2019-03-04 09:57:27.250746 ERROR alert_manager.py:63 Fanning out RPC
2019-03-04 09:57:28.252085 DBG gflags_handler.py:219 Combining logs from all nodes into single log file
2019-03-04 09:57:38.263781 DBG wsgi_handler.py:222 Node destroyed
2019-03-04 09:57:39.264777 INFO http_handler.py:208 Node destroyed
2019-03-04 09:57:41.266991 ERROR alert_manager.py:303 Generated binary file
2019-03-04 09:57:48.277294 INFO fanout.py:162 Gathering logs from all nodes
2019-03-04 09:57:49.278495 INFO db_write.py:252 Creating task
2019-03-04 09:57:51.281291 ERROR gflags_handler.py:149 Generated binary file
2019-03-04 09:57:57.289933 DBG log_collector.py:135 Node created
2019-03-04 09:57:59.292226 DBG fanout.py:112 Fanning out RPC
2019-03-04 09:58:06.299092 INFO scheduler.py:214 Gathering logs from all nodes
Traceback (most recent call last):
  File "./random_traceback.py", line 98, in get_random_error_string
  File "./random_traceback.py", line 59, in get_data
BasicAuthRequiredError: Password not provided
2019-03-04 09:58:30.343030 INFO log_collector.py:203 Combining logs from all nodes into single log file
2019-03-04 09:58:38.352276 INFO audit_logger.py:217 Combining logs from all nodes into single log file
2019-03-04 09:59:03.384316 INFO ssh_tunnel.py:396 Generated binary file
2019-03-04 09:59:09.390982 DBG protobuf_parser.py:228 Node destroyed
2019-03-04 09:59:15.399146 INFO scheduler.py:21 Combining logs from all nodes into single log file
2019-03-04 09:59:30.418043 ERROR alert_manager.py:274 Combining logs from all nodes into single log file
2019-03-04 09:59:31.419301 DBG log_collector.py:108 Fanning out RPC
2019-03-04 09:59:32.420563 ERROR ssh_tunnel.py:68 Creating task
2019-03-04 09:59:33.421773 INFO db_read.py:195 Generated binary file
2019-03-04 09:59:44.435457 ERROR rpc_client.py:220 Generated binary file
2019-03-04 09:59:50.443150 ERROR alert_manager.py:39 Gathering node data
2019-03-04 09:59:56.450762 INFO audit_logger.py:149 Gathering node data
2019-03-04 10:00:08.464058 DBG db_read.py:377 Gathering node data
2019-03-04 10:00:11.467012 INFO audit_logger.py:276 Combining logs from all nodes into single log file
2019-03-04 10:00:15.472980 INFO wsgi_handler.py:142 Node created
2019-03-04 10:00:17.475406 INFO publisher.py:82 Fanning out RPC
2019-03-04 10:00:22.481736 INFO task_generator.py:205 Combining logs from all nodes into single log file
2019-03-04 10:00:24.484294 ERROR db_read.py:45 Combining logs from all nodes into single log file
2019-03-04 10:00:30.491895 ERROR fanout.py:121 Creating task
2019-03-04 10:00:34.496971 ERROR protobuf_parser.py:270 Creating task
2019-03-04 10:00:39.503326 ERROR scheduler.py:277 Gathering node data
Traceback (most recent call last):
  File "./random_traceback.py", line 98, in get_random_error_string
  File "./random_traceback.py", line 59, in get_data
InvalidArgumentError: Arguments not supported
2019-03-04 10:00:41.505968 DBG wsgi_handler.py:207 Generated binary file
2019-03-04 10:00:43.508677 INFO db_write.py:376 Combining logs from all nodes into single log file
2019-03-04 10:00:47.513880 DBG gflags_handler.py:388 Gathering node data
2019-03-04 10:00:49.516314 ERROR alert_manager.py:141 Generated binary file
2019-03-04 10:00:51.518861 INFO http_handler.py:216 Node created
2019-03-04 10:01:01.531364 ERROR wsgi_handler.py:331 Creating task
Traceback (most recent call last):
  File "./random_traceback.py", line 113, in get_random_error_string
  File "./random_traceback.py", line 92, in get_attributes
BasicAuthRequiredError: Username not provided
2019-03-04 10:01:09.541745 DBG wsgi_handler.py:40 Node destroyed
2019-03-04 10:01:17.552372 DBG http_handler.py:392 Gathering node data
2019-03-04 10:01:39.580798 ERROR protobuf_parser.py:184 Creating task
2019-03-04 10:01:48.592213 DBG protobuf_parser.py:84 Gathering node data
2019-03-04 10:01:49.593426 ERROR db_write.py:91 Gathering logs from all nodes
2019-03-04 10:01:51.595961 ERROR wsgi_handler.py:289 Node created
2019-03-04 10:01:54.599749 DBG http_handler.py:188 Creating task
2019-03-04 10:02:07.615842 DBG fanout.py:367 Node created
Traceback (most recent call last):
  File "./random_traceback.py", line 113, in get_random_error_string
  File "./random_traceback.py", line 92, in get_attributes
MissingAttributeError: Attribute missing
Traceback (most recent call last):
  File "./random_traceback.py", line 108, in get_random_error_string
  File "./random_traceback.py", line 75, in return_output
  File "./random_traceback.py", line 70, in extract_metadata
ConflictError: Conflicting data types
2019-03-04 10:02:22.634227 DBG db_read.py:9 Node destroyed
Traceback (most recent call last):
  File "./random_traceback.py", line 98, in get_random_error_string
  File "./random_traceback.py", line 59, in get_data
InvalidArgumentError: Provided too few arguments
2019-03-04 10:02:39.655004 INFO http_handler.py:272 Node created
Traceback (most recent call last):
  File "./random_traceback.py", line 103, in get_random_error_string
  File "./random_traceback.py", line 66, in extract_metadata
  File "./random_traceback.py", line 77, in return_output
  File "./random_traceback.py", line 53, in get_data
  File "./random_traceback.py", line 70, in extract_metadata
MissingAttributeError: Attribute missing
2019-03-04 10:02:49.666746 ERROR wsgi_handler.py:331 Creating task
2019-03-04 10:02:52.670425 INFO gflags_handler.py:377 Combining logs from all nodes into single log file
2019-03-04 10:02:56.674907 INFO db_write.py:384 Combining logs from all nodes into single log file
2019-03-04 10:02:58.677423 ERROR protobuf_parser.py:267 Node destroyed
2019-03-04 10:03:03.682541 ERROR publisher.py:27 Fanning out RPC
Traceback (most recent call last):
  File "./random_traceback.py", line 113, in get_random_error_string
  File "./random_traceback.py", line 88, in get_attributes
  File "./random_traceback.py", line 92, in get_attributes
InvalidArgumentError: Arguments not supported
2019-03-04 10:03:19.700262 ERROR protobuf_parser.py:163 Gathering logs from all nodes
2019-03-04 10:03:21.702817 DBG http_handler.py:280 Gathering logs from all nodes
2019-03-04 10:03:46.736863 ERROR rpc_client.py:333 Fanning out RPC
Traceback (most recent call last):
  File "./random_traceback.py", line 103, in get_random_error_string
  File "./random_traceback.py", line 64, in extract_metadata
  File "./random_traceback.py", line 86, in get_attributes
  File "./random_traceback.py", line 59, in get_data
InvalidArgumentError: Provided too few arguments
2019-03-04 10:03:52.745613 DBG http_handler.py:294 Creating task
2019-03-04 10:03:55.749646 INFO fanout.py:114 Fanning out RPC
Traceback (most recent call last):
  File "./random_traceback.py", line 108, in get_random_error_string
  File "./random_traceback.py", line 75, in return_output
  File "./random_traceback.py", line 64, in extract_metadata
  File "./random_traceback.py", line 88, in get_attributes
  File "./random_traceback.py", line 88, in get_attributes
  File "./random_traceback.py", line 92, in get_attributes
InvalidArgumentError: Provided too many arguments
2019-03-04 10:04:07.767127 DBG gflags_handler.py:7 Node created
2019-03-04 10:04:15.779062 ERROR wsgi_handler.py:388 Node created
2019-03-04 10:04:17.782110 DBG log_collector.py:293 Generated binary file
2019-03-04 10:04:24.792207 INFO gflags_handler.py:141 Combining logs from all nodes into single log file
2019-03-04 10:04:29.798619 DBG wsgi_handler.py:254 Gathering logs from all nodes
2019-03-04 10:04:34.804929 ERROR alert_manager.py:42 Fanning out RPC
2019-03-04 10:04:42.814949 DBG gflags_handler.py:374 Creating task
2019-03-04 10:04:48.822270 ERROR wsgi_handler.py:13 Gathering node data
2019-03-04 10:05:05.843807 DBG rpc_client.py:101 Gathering logs from all nodes
2019-03-04 10:05:09.848843 ERROR http_handler.py:373 Generated binary file
2019-03-04 10:05:16.857660 INFO task_generator.py:258 Gathering logs from all nodes
2019-03-04 10:05:23.867823 DBG task_generator.py:27 Node created
2019-03-04 10:05:24.869131 INFO wsgi_handler.py:202 Fanning out RPC
