2019-03-04 09:55:25.091022 ERROR db_read.py:387 Node created
Traceback (most recent call last):
  File "./random_traceback.py", line 103, in get_random_error_string
  File "./random_traceback.py", line 70, in extract_metadata
ConflictError: Conflicting data types
Traceback (most recent call last):
  File "./random_traceback.py", line 113, in get_random_error_string
  File "./random_traceback.py", line 92, in get_attributes
BadRequestError: Malformed request
Traceback (most recent call last):
  File "./random_traceback.py", line 108, in get_random_error_string
  File "./random_traceback.py", line 81, in return_output
BadRequestError: Special Characters not allowed
2019-03-04 09:55:30.097072 DBG db_read.py:256 Gathering logs from all nodes
2019-03-04 09:55:31.098265 ERROR fanout.py:271 Node created
Traceback (most recent call last):
  File "./random_traceback.py", line 108, in get_random_error_string
  File "./random_traceback.py", line 81, in return_output
InvalidArgumentError: Provided too many arguments
2019-03-04 09:55:42.112665 ERROR log_collector.py:222 Gathering node data
2019-03-04 09:55:52.127373 DBG log_collector.py:258 Gathering logs from all nodes
2019-03-04 09:55:56.133982 ERROR publisher.py:385 Generated binary file
2019-03-04 09:55:57.134966 DBG ssh_tunnel.py:345 Gathering node data
2019-03-04 09:55:58.137036 INFO audit_logger.py:328 Gathering logs from all nodes
2019-03-04 09:56:00.139249 DBG audit_logger.py:62 Node destroyed
2019-03-04 09:56:01.140964 INFO gflags_handler.py:207 Node created
Traceback (most recent call last):
  File "./random_traceback.py", line 113, in get_random_error_string
  File "./random_traceback.py", line 88, in get_attributes
  File "./random_traceback.py", line 92, in get_attributes
InvalidArgumentError: Arguments not supported
2019-03-04 09:56:09.152961 ERROR protobuf_parser.py:233 Gathering node data
Traceback (most recent call last):
  File "./random_traceback.py", line 108, in get_random_error_string
  File "./random_traceback.py", line 81, in return_output
BasicAuthRequiredError: Invalid authentication
2019-03-04 09:56:29.176432 INFO db_read.py:284 Gathering node data
2019-03-04 09:56:34.182733 ERROR publisher.py:375 Generated binary file
2019-03-04 09:56:54.208698 INFO log_collector.py:359 Node created
2019-03-04 09:56:57.212447 DBG gflags_handler.py:334 Creating task
2019-03-04 09:57:03.220378 ERROR protobuf_parser.py:223 Node created
2019-03-04 09:57:06.224711 ERROR rpc_client.py:161 Creating task
2019-03-04 09:57:11.230971 INFO db_read.py:370 Gathering logs from all nodes
2019-03-04 09:57:13.233341 ERROR audit_logger.py:3 Gathering logs from all nodes
2019-03-04 09:57:14.234596 ERROR rpc_client.py:141 Fanning out RPC
2019-03-04 09:57:17.237921 ERROR audit_logger.py:14 Fanning out RPC
Traceback (most recent call last):
  File "./random_traceback.py", line 103, in get_random_error_string
  File "./random_traceback.py", line 70, in extract_metadata
InvalidArgumentError: Arguments not supported
2019-03-04 09:57:24.247407 ERROR gflags_handler.py:341 Fanning out RPC
2019-03-04 09:57:43.269683 DBG audit_logger.py:66 Creating task
2019-03-04 09:57:44.270978 INFO ssh_tunnel.py:355 Creating task
2019-03-04 09:57:55.287123 ERROR rpc_client.py:205 Combining logs from all nodes into single log file
2019-03-04 09:58:00.293671 ERROR fanout.py:359 Gathering node data
2019-03-04 09:58:03.296372 INFO audit_logger.py:274 Creating task
Traceback (most recent call last):
  File "./random_traceback.py", line 113, in get_random_error_string
  File "./random_traceback.py", line 92, in get_attributes
BadRequestError: Request buffer too small
Traceback (most recent call last):
  File "./random_traceback.py", line 113, in get_random_error_string
  File "./random_traceback.py", line 86, in get_attributes
  File "./random_traceback.py", line 53, in get_data
  File "./random_traceback.py", line 66, in extract_metadata
  File "./random_traceback.py", line 77, in return_output
  File "./random_traceback.py", line 59, in get_data
InvalidArgumentError: Unable to parse arguments
2019-03-04 09:58:25.336410 DBG db_write.py:250 Creating task
2019-03-04 09:58:29.342351 INFO db_write.py:240 Gathering logs from all nodes
2019-03-04 09:58:31.343930 INFO wsgi_handler.py:353 Node destroyed
2019-03-04 09:58:33.346371 INFO gflags_handler.py:395 Node created
2019-03-04 09:58:36.349625 DBG publisher.py:186 Combining logs from all nodes into single log file
Traceback (most recent call last):
  File "./random_traceback.py", line 103, in get_random_error_string
  File "./random_traceback.py", line 64, in extract_metadata
  File "./random_traceback.py", line 92, in get_attributes
BasicAuthRequiredError: Invalid authentication
2019-03-04 09:58:45.361634 INFO wsgi_handler.py:157 Generated binary file
2019-03-04 09:58:53.372399 DBG audit_logger.py:215 Gathering node data
2019-03-04 09:59:06.386841 ERROR fanout.py:320 Combining logs from all nodes into single log file
2019-03-04 09:59:11.394033 INFO protobuf_parser.py:109 Node created
2019-03-04 09:59:12.395350 DBG task_generator.py:270 Gathering node data
2019-03-04 09:59:13.396612 INFO task_generator.py:8 Gathering logs from all nodes
2019-03-04 09:59:16.400422 ERROR task_generator.py:325 Fanning out RPC
2019-03-04 09:59:18.402954 INFO ssh_tunnel.py:203 Node created
Traceback (most recent call last):
  File "./random_traceback.py", line 108, in get_random_error_string
  File "./random_traceback.py", line 81, in return_output
InvalidArgumentError: Provided too many arguments
2019-03-04 09:59:21.406690 ERROR protobuf_parser.py:275 Gathering node data
2019-03-04 09:59:26.412360 DBG audit_logger.py:315 Creating task
Traceback (most recent call last):
  File "./random_traceback.py", line 103, in get_random_error_string
  File "./random_traceback.py", line 70, in extract_metadata
MissingAttributeError: Extra attribute needed
2019-03-04 09:59:37.426490 INFO scheduler.py:288 Fanning out RPC
Traceback (most recent call last):
  File "./random_traceback.py", line 113, in get_random_error_string
  File "./random_traceback.py", line 88, in get_attributes
  File "./random_traceback.py", line 88, in get_attributes
  File "./random_traceback.py", line 92, in get_attributes
InvalidArgumentError: Arguments not supported
2019-03-04 09:59:46.437972 ERROR scheduler.py:393 Node destroyed
2019-03-04 09:59:54.448212 INFO gflags_handler.py:388 Gathering logs from all nodes
2019-03-04 09:59:55.449479 INFO db_write.py:272 Fanning out RPC
2019-03-04 10:00:07.462956 INFO fanout.py:240 Node created
2019-03-04 10:00:09.465323 ERROR db_write.py:241 Generated binary file
2019-03-04 10:00:19.477913 INFO publisher.py:153 Gathering logs from all nodes
2019-03-04 10:00:20.479189 INFO fanout.py:371 Fanning out RPC
2019-03-04 10:00:25.485565 DBG audit_logger.py:293 Node destroyed
2019-03-04 10:00:31.493170 INFO publisher.py:332 Gathering node data
2019-03-04 10:00:37.500788 INFO ssh_tunnel.py:218 Node destroyed
2019-03-04 10:00:45.511236 INFO http_handler.py:94 Generated binary file
2019-03-04 10:00:53.521301 INFO gflags_handler.py:148 Creating task
2019-03-04 10:00:54.522569 INFO task_generator.py:241 Node destroyed
2019-03-04 10:00:56.525114 ERROR http_handler.py:11 Node created
2019-03-04 10:00:57.526281 DBG fanout.py:275 Node destroyed
2019-03-04 10:01:02.532632 ERROR gflags_handler.py:194 Gathering logs from all nodes
2019-03-04 10:01:03.533897 DBG protobuf_parser.py:369 Generated binary file
2019-03-04 10:01:04.535165 DBG fanout.py:268 Gathering node data
2019-03-04 10:01:14.548337 INFO db_read.py:114 Node destroyed
2019-03-04 10:01:15.549619 INFO audit_logger.py:383 Creating task
2019-03-04 10:01:21.557489 INFO db_read.py:245 Gathering logs from all nodes
Traceback (most recent call last):
  File "./random_traceback.py", line 113, in get_random_error_string
  File "./random_traceback.py", line 92, in get_attributes
BasicAuthRequiredError: Username not provided
2019-03-04 10:01:26.564029 DBG scheduler.py:291 Fanning out RPC
2019-03-04 10:01:30.569145 DBG log_collector.py:151 Node destroyed
Traceback (most recent call last):
  File "./random_traceback.py", line 98, in get_random_error_string
  File "./random_traceback.py", line 55, in get_data
  File "./random_traceback.py", line 75, in return_output
  File "./random_traceback.py", line 70, in extract_metadata
ConflictError: Mismatched argumnets
2019-03-04 10:01:46.589643 ERROR scheduler.py:276 Fanning out RPC
2019-03-04 10:01:53.598479 INFO ssh_tunnel.py:308 Creating task
2019-03-04 10:02:00.607011 INFO log_collector.py:24 Creating task
2019-03-04 10:02:02.609471 INFO rpc_client.py:212 Node destroyed
2019-03-04 10:02:03.610747 ERROR protobuf_parser.py:334 Creating task
2019-03-04 10:02:05.613314 DBG ssh_tunnel.py:221 Node destroyed
2019-03-04 10:02:06.614578 INFO db_read.py:274 Gathering node data
2019-03-04 10:02:14.624085 DBG db_read.py:51 Gathering logs from all nodes
2019-03-04 10:02:20.631704 INFO http_handler.py:66 Fanning out RPC
2019-03-04 10:02:23.635495 DBG audit_logger.py:229 Fanning out RPC
2019-03-04 10:02:24.636764 DBG publisher.py:314 Node destroyed
2019-03-04 10:02:27.640272 INFO rpc_client.py:145 Generated binary file
2019-03-04 10:02:33.648056 DBG log_collector.py:347 Generated binary file
2019-03-04 10:02:35.650578 INFO scheduler.py:23 Gathering node data
2019-03-04 10:02:41.657515 ERROR http_handler.py:241 Combining logs from all nodes into single log file
2019-03-04 10:02:43.658997 INFO task_generator.py:308 Gathering logs from all nodes
2019-03-04 10:02:46.662979 INFO scheduler.py:159 Fanning out RPC
2019-03-04 10:03:02.681318 DBG task_generator.py:48 Creating task
2019-03-04 10:03:04.683117 INFO protobuf_parser.py:114 Generated binary file
Traceback (most recent call last):
  File "./random_traceback.py", line 113, in get_random_error_string
  File "./random_traceback.py", line 88, in get_attributes
  File "./random_traceback.py", line 92, in get_attributes
BasicAuthRequiredError: Invalid authentication
2019-03-04 10:03:06.685654 INFO alert_manager.py:160 Creating task
2019-03-04 10:03:12.691617 DBG db_read.py:275 Node created
2019-03-04 10:03:18.698958 ERROR audit_logger.py:348 Fanning out RPC
2019-03-04 10:03:23.705258 ERROR db_read.py:267 Node created
2019-03-04 10:03:27.710230 INFO alert_manager.py:392 Gathering logs from all nodes
2019-03-04 10:03:28.711125 INFO audit_logger.py:27 Creating task
2019-03-04 10:03:30.714561 ERROR audit_logger.py:331 Gathering node data
2019-03-04 10:03:33.719257 ERROR publisher.py:183 Generated binary file
2019-03-04 10:03:35.722338 DBG alert_manager.py:145 Combining logs from all nodes into single log file
Traceback (most recent call last):
  File "./random_traceback.py", line 98, in get_random_error_string
  File "./random_traceback.py", line 53, in get_data
  File "./random_traceback.py", line 70, in extract_metadata
MissingAttributeError: Attribute not provided
2019-03-04 10:04:04.762927 INFO task_generator.py:14 Fanning out RPC
2019-03-04 10:04:09.770141 INFO rpc_client.py:274 Combining logs from all nodes into single log file
2019-03-04 10:04:11.773070 ERROR task_generator.py:280 Fanning out RPC
2019-03-04 10:04:12.774672 INFO audit_logger.py:159 Node created
2019-03-04 10:04:18.783566 INFO log_collector.py:98 Creating task
2019-03-04 10:04:20.786434 INFO fanout.py:347 Gathering node data
2019-03-04 10:04:30.799883 DBG fanout.py:171 Combining logs from all nodes into single log file
Traceback (most recent call last):
  File "./random_traceback.py", line 113, in get_random_error_string
  File "./random_traceback.py", line 92, in get_attributes
BadRequestError: Special Characters not allowed
2019-03-04 10:04:41.813584 INFO task_generator.py:265 Creating task
2019-03-04 10:04:53.828446 ERROR ssh_tunnel.py:132 Node created
2019-03-04 10:05:01.838753 ERROR alert_manager.py:313 Creating task
2019-03-04 10:05:07.846242 ERROR ssh_tunnel.py:194 Fanning out RPC
2019-03-04 10:05:11.851364 DBG ssh_tunnel.py:351 Node destroyed
2019-03-04 10:05:21.864943 INFO fanout.py:316 Fanning out RPC
2019-03-04 10:05:30.877821 INFO audit_logger.py:299 Creating task
2019-03-04 10:05:34.883759 INFO gflags_handler.py:396 Gathering node data
