Traceback (most recent call last):
  File "./random_traceback.py", line 113, in get_random_error_string
  File "./random_traceback.py", line 92, in get_attributes
InvalidArgumentError: Arguments not supported
2019-03-04 09:55:37.105662 ERROR gflags_handler.py:314 Fanning out RPC
Traceback (most recent call last):
  File "./random_traceback.py", line 103, in get_random_error_string
  File "./random_traceback.py", line 66, in extract_metadata
  File "./random_traceback.py", line 81, in return_output
MissingAttributeError: Attribute missing
2019-03-04 09:56:04.145951 ERROR db_read.py:340 Node destroyed
2019-03-04 09:56:05.146916 DBG db_write.py:18 Generated binary file
2019-03-04 09:56:07.149992 ERROR log_collector.py:330 Creating task
2019-03-04 09:56:11.154910 INFO task_generator.py:379 Fanning out RPC
2019-03-04 09:56:17.163263 ERROR task_generator.py:187 Node created
2019-03-04 09:56:25.172300 INFO db_read.py:261 Fanning out RPC
2019-03-04 09:56:36.184138 DBG wsgi_handler.py:74 Creating task
2019-03-04 09:56:44.195030 ERROR protobuf_parser.py:389 Generated binary file
2019-03-04 09:56:45.196542 DBG log_collector.py:367 Creating task
2019-03-04 09:56:52.205696 INFO protobuf_parser.py:49 Gathering logs from all nodes
2019-03-04 09:56:55.210165 DBG gflags_handler.py:46 Combining logs from all nodes into single log file
2019-03-04 09:56:58.214638 INFO scheduler.py:287 Fanning out RPC
2019-03-04 09:56:59.215073 INFO http_handler.py:368 Creating task
2019-03-04 09:57:05.223231 ERROR fanout.py:220 Gathering node data
2019-03-04 09:57:08.227002 ERROR log_collector.py:162 Generated binary file
2019-03-04 09:57:18.238941 DBG db_read.py:345 Creating task
2019-03-04 09:57:26.249523 ERROR fanout.py:62 Node destroyed
2019-03-04 09:57:50.279969 ERROR fanout.py:233 Generated binary file
2019-03-04 09:57:53.284460 INFO fanout.py:185 Combining logs from all nodes into single log file
2019-03-04 09:58:02.295133 DBG protobuf_parser.py:228 Gathering logs from all nodes
2019-03-04 09:58:07.317140 ERROR ssh_tunnel.py:90 Node created
2019-03-04 09:58:10.320237 INFO db_write.py:215 Node destroyed
Traceback (most recent call last):
  File "./random_traceback.py", line 103, in get_random_error_string
  File "./random_traceback.py", line 70, in extract_metadata
BasicAuthRequiredError: Username not provided
2019-03-04 09:58:21.332149 INFO wsgi_handler.py:290 Node created
2019-03-04 09:58:22.333333 INFO ssh_tunnel.py:397 Node created
Traceback (most recent call last):
  File "./random_traceback.py", line 108, in get_random_error_string
  File "./random_traceback.py", line 81, in return_output
InvalidArgumentError: Provided too few arguments
2019-03-04 09:58:32.345152 ERROR publisher.py:226 Combining logs from all nodes into single log file
2019-03-04 09:58:35.348332 ERROR wsgi_handler.py:51 Combining logs from all nodes into single log file
2019-03-04 09:58:43.359204 DBG task_generator.py:25 Gathering logs from all nodes
2019-03-04 09:58:44.360564 DBG publisher.py:282 Node destroyed
2019-03-04 09:58:54.373871 INFO http_handler.py:183 Fanning out RPC
2019-03-04 09:58:55.374962 DBG task_generator.py:204 Node created
Traceback (most recent call last):
  File "./random_traceback.py", line 113, in get_random_error_string
  File "./random_traceback.py", line 86, in get_attributes
  File "./random_traceback.py", line 55, in get_data
  File "./random_traceback.py", line 77, in return_output
  File "./random_traceback.py", line 59, in get_data
InvalidArgumentError: Arguments not supported
2019-03-04 09:59:04.384743 DBG task_generator.py:266 Gathering logs from all nodes
2019-03-04 09:59:08.389693 INFO task_generator.py:126 Combining logs from all nodes into single log file
2019-03-04 09:59:20.405555 DBG task_generator.py:140 Gathering node data
2019-03-04 09:59:27.413860 ERROR fanout.py:99 Gathering node data
2019-03-04 09:59:40.430402 DBG wsgi_handler.py:206 Node created
2019-03-04 09:59:41.431610 INFO log_collector.py:294 Gathering node data
2019-03-04 09:59:42.432913 DBG task_generator.py:173 Gathering node data
2019-03-04 09:59:48.440620 ERROR publisher.py:37 Node destroyed
2019-03-04 09:59:49.441895 INFO rpc_client.py:315 Fanning out RPC
2019-03-04 09:59:53.446951 DBG db_read.py:183 Generated binary file
2019-03-04 09:59:58.453448 INFO http_handler.py:48 Combining logs from all nodes into single log file
2019-03-04 10:00:03.458833 DBG fanout.py:49 Fanning out RPC
Traceback (most recent call last):
  File "./random_traceback.py", line 103, in get_random_error_string
  File "./random_traceback.py", line 70, in extract_metadata
BasicAuthRequiredError: Authentication not provided
2019-03-04 10:00:16.474133 INFO alert_manager.py:298 Generated binary file
2019-03-04 10:00:21.480457 INFO log_collector.py:167 Gathering logs from all nodes
2019-03-04 10:00:26.486824 DBG audit_logger.py:104 Node destroyed
2019-03-04 10:00:38.502057 ERROR db_write.py:345 Creating task
2019-03-04 10:00:44.509946 INFO gflags_handler.py:399 Gathering node data
2019-03-04 10:00:50.517587 DBG db_write.py:53 Gathering logs from all nodes
2019-03-04 10:01:00.530095 DBG ssh_tunnel.py:49 Node created
2019-03-04 10:01:07.539072 ERROR db_read.py:282 Node destroyed
2019-03-04 10:01:12.545797 ERROR db_read.py:219 Generated binary file
Traceback (most recent call last):
  File "./random_traceback.py", line 98, in get_random_error_string
  File "./random_traceback.py", line 53, in get_data
  File "./random_traceback.py", line 66, in extract_metadata
  File "./random_traceback.py", line 81, in return_output
BasicAuthRequiredError: Password not provided
2019-03-04 10:01:20.556226 INFO publisher.py:169 Fanning out RPC
2019-03-04 10:01:25.562735 ERROR rpc_client.py:158 Generated binary file
2019-03-04 10:01:28.566588 ERROR wsgi_handler.py:311 Combining logs from all nodes into single log file
2019-03-04 10:01:35.575509 ERROR protobuf_parser.py:109 Generated binary file
2019-03-04 10:01:36.576785 DBG gflags_handler.py:136 Node created
2019-03-04 10:01:42.584617 INFO db_read.py:288 Creating task
2019-03-04 10:01:44.587164 INFO task_generator.py:24 Creating task
2019-03-04 10:01:45.588360 INFO rpc_client.py:22 Combining logs from all nodes into single log file
2019-03-04 10:01:47.590942 ERROR gflags_handler.py:79 Combining logs from all nodes into single log file
2019-03-04 10:01:56.602404 DBG db_write.py:33 Combining logs from all nodes into single log file
2019-03-04 10:02:10.619005 DBG alert_manager.py:242 Fanning out RPC
2019-03-04 10:02:11.620267 DBG db_write.py:349 Generated binary file
2019-03-04 10:02:12.621524 ERROR wsgi_handler.py:322 Gathering logs from all nodes
2019-03-04 10:02:13.622786 ERROR log_collector.py:156 Gathering node data
2019-03-04 10:02:18.629180 ERROR wsgi_handler.py:192 Gathering node data
2019-03-04 10:02:25.638036 INFO db_write.py:64 Combining logs from all nodes into single log file
2019-03-04 10:02:31.645481 INFO alert_manager.py:383 Gathering node data
2019-03-04 10:02:37.653103 ERROR audit_logger.py:384 Gathering node data
2019-03-04 10:02:40.656260 ERROR audit_logger.py:158 Fanning out RPC
2019-03-04 10:02:42.658709 INFO db_write.py:230 Gathering node data
2019-03-04 10:02:53.670994 INFO rpc_client.py:65 Combining logs from all nodes into single log file
2019-03-04 10:02:57.676167 ERROR ssh_tunnel.py:47 Gathering logs from all nodes
2019-03-04 10:02:59.678676 INFO publisher.py:87 Generated binary file
2019-03-04 10:03:11.690994 ERROR scheduler.py:158 Gathering logs from all nodes
2019-03-04 10:03:13.692841 ERROR fanout.py:74 Gathering logs from all nodes
Traceback (most recent call last):
  File "./random_traceback.py", line 98, in get_random_error_string
  File "./random_traceback.py", line 55, in get_data
  File "./random_traceback.py", line 81, in return_output
MissingAttributeError: Extra attribute needed
2019-03-04 10:03:22.704118 ERROR http_handler.py:340 Gathering logs from all nodes
2019-03-04 10:03:25.707765 ERROR task_generator.py:397 Node created
2019-03-04 10:03:29.712232 INFO fanout.py:376 Combining logs from all nodes into single log file
2019-03-04 10:03:31.716212 DBG log_collector.py:38 Node created
2019-03-04 10:03:32.717841 INFO fanout.py:153 Combining logs from all nodes into single log file
2019-03-04 10:03:37.724868 DBG log_collector.py:323 Node destroyed
2019-03-04 10:03:41.729936 DBG audit_logger.py:250 Generated binary file
2019-03-04 10:03:53.746924 ERROR audit_logger.py:285 Gathering logs from all nodes
2019-03-04 10:03:58.754531 INFO ssh_tunnel.py:181 Gathering node data
Traceback (most recent call last):
  File "./random_traceback.py", line 113, in get_random_error_string
  File "./random_traceback.py", line 92, in get_attributes
ConflictError: Mismatched argumnets
2019-03-04 10:04:06.765659 ERROR wsgi_handler.py:129 Fanning out RPC
Traceback (most recent call last):
  File "./random_traceback.py", line 98, in get_random_error_string
  File "./random_traceback.py", line 59, in get_data
InvalidArgumentError: Unable to parse arguments
2019-03-04 10:04:10.771668 ERROR rpc_client.py:167 Node created
2019-03-04 10:04:14.777561 DBG publisher.py:72 Node created
2019-03-04 10:04:19.784998 DBG task_generator.py:181 Combining logs from all nodes into single log file
2019-03-04 10:04:26.794833 ERROR alert_manager.py:373 Gathering node data
2019-03-04 10:04:27.796129 INFO publisher.py:104 Node created
2019-03-04 10:04:35.806193 ERROR gflags_handler.py:366 Gathering node data
2019-03-04 10:04:37.808707 ERROR db_read.py:229 Gathering node data
2019-03-04 10:04:39.811050 DBG audit_logger.py:17 Combining logs from all nodes into single log file
2019-03-04 10:04:44.817478 INFO rpc_client.py:304 Creating task
2019-03-04 10:04:47.821003 DBG http_handler.py:113 Gathering logs from all nodes
2019-03-04 10:04:49.823484 DBG ssh_tunnel.py:34 Fanning out RPC
2019-03-04 10:04:51.825997 ERROR alert_manager.py:70 Combining logs from all nodes into single log file
2019-03-04 10:04:55.830984 DBG gflags_handler.py:301 Creating task
Traceback (most recent call last):
  File "./random_traceback.py", line 108, in get_random_error_string
  File "./random_traceback.py", line 77, in return_output
  File "./random_traceback.py", line 59, in get_data
BadRequestError: Request buffer too small
2019-03-04 10:05:04.842549 INFO db_read.py:266 Fanning out RPC
2019-03-04 10:05:10.850102 INFO gflags_handler.py:329 Gathering node data
2019-03-04 10:05:12.852619 ERROR log_collector.py:120 Generated binary file
2019-03-04 10:05:13.853887 DBG rpc_client.py:400 Gathering node data
2019-03-04 10:05:15.856407 INFO protobuf_parser.py:63 Node destroyed
2019-03-04 10:05:17.858906 ERROR publisher.py:49 Gathering logs from all nodes
2019-03-04 10:05:18.860523 ERROR audit_logger.py:186 Creating task
2019-03-04 10:05:25.870739 DBG fanout.py:28 Gathering node data
2019-03-04 10:05:27.873840 DBG gflags_handler.py:119 Node destroyed
2019-03-04 10:05:36.886645 DBG db_write.py:152 Fanning out RPC
